<?xml version="1.0" ?>
<!-- =================================================================================== -->
<!-- |    This document was autogenerated by xacro from robots/arm_7dof.urdf.xacro     | -->
<!-- |    EDITING THIS FILE BY HAND IS NOT RECOMMENDED                                 | -->
<!-- =================================================================================== -->
<robot name="ballbotArm" xmlns:xacro="http://ros.org/wiki/xacro">
  <material name="yellow">
    <color rgba="1 1 0 1"/>
  </material>
  <!-- Use of macros to assemble the robot -->
  <link name="base_link">
    <visual>
      <origin rpy="0 1.5707963268 3.14159265359" xyz="0 0 0"/>
      <geometry>
        <mesh filename="package://ballbot_arm_description/meshes/link_base.stl"/>
      </geometry>
    </visual>
    <collision>
      <origin rpy="0 1.5707963268 3.14159265359" xyz="0 0 0"/>
      <geometry>
        <mesh filename="package://ballbot_arm_description/meshes/link_base.stl"/>
      </geometry>
    </collision>
  </link>
  <joint name="shoulder_1_joint" type="revolute">
    <origin rpy="1.5707963268 0 -1.5707963268" xyz="0 0 0"/>
    <axis xyz="0 0 1"/>
    <limit effort="30" lower="-3.14159265359" upper="3.14159265359" velocity="1.0"/>
    <parent link="base_link"/>
    <child link="shoulder_2_base_link"/>
  </joint>
  <link name="shoulder_2_base_link">
    <visual>
      <origin rpy="0 1.5707963268 3.14159265359" xyz="0 0 0"/>
      <geometry>
        <mesh filename="package://ballbot_arm_description/meshes/link_shoulder_2_base.stl"/>
      </geometry>
    </visual>
    <collision>
      <origin rpy="0 1.5707963268 3.14159265359" xyz="0 0 0"/>
      <geometry>
        <mesh filename="package://ballbot_arm_description/meshes/link_shoulder_2_base.stl"/>
      </geometry>
    </collision>
  </link>
  <joint name="shoulder_2_joint" type="revolute">
    <origin rpy="0 -1.5707963268 0" xyz="0 0 0.15"/>
    <axis xyz="0 0 1"/>
    <limit effort="30" lower="-1.5707963268" upper="1.5707963268" velocity="1.0"/>
    <parent link="shoulder_2_base_link"/>
    <child link="shoulder_2_uparm_link"/>
  </joint>
  <link name="shoulder_2_uparm_link">
    <visual>
      <origin rpy="3.14159265359 0 1.5707963268" xyz="0 0 0"/>
      <geometry>
        <mesh filename="package://ballbot_arm_description/meshes/link_shoulder_2_uparm.stl"/>
      </geometry>
    </visual>
    <collision>
      <origin rpy="3.14159265359 0 1.5707963268" xyz="0 0 0"/>
      <geometry>
        <mesh filename="package://ballbot_arm_description/meshes/link_shoulder_2_uparm.stl"/>
      </geometry>
    </collision>
  </link>
  <joint name="shoulder_3_joint" type="revolute">
    <origin rpy="-1.5707963268 0 0" xyz="0 -0.150683 0"/>
    <axis xyz="0 0 1"/>
    <limit effort="30" lower="-3.14159265359" upper="3.14159265359" velocity="1.0"/>
    <parent link="shoulder_2_uparm_link"/>
    <child link="uparm_link"/>
  </joint>
  <link name="uparm_link">
    <visual>
      <origin rpy="0 0 1.5707963268" xyz="0 0 0"/>
      <geometry>
        <mesh filename="package://ballbot_arm_description/meshes/link_uparm.stl"/>
      </geometry>
    </visual>
    <collision>
      <origin rpy="0 0 1.5707963268" xyz="0 0 0"/>
      <geometry>
        <mesh filename="package://ballbot_arm_description/meshes/link_uparm.stl"/>
      </geometry>
    </collision>
  </link>
  <joint name="elbow_joint" type="revolute">
    <origin rpy="0 1.5707963268 0" xyz="0 0 -0.112431"/>
    <axis xyz="0 0 1"/>
    <limit effort="30" lower="0" upper="2.26892802759" velocity="1.0"/>
    <parent link="uparm_link"/>
    <child link="forearm_link"/>
  </joint>
  <link name="forearm_link">
    <visual>
      <origin rpy="0 0 0" xyz="0 0 0"/>
      <geometry>
        <mesh filename="package://ballbot_arm_description/meshes/link_forearm.stl"/>
      </geometry>
    </visual>
    <collision>
      <origin rpy="0 0 0" xyz="0 0 0"/>
      <geometry>
        <mesh filename="package://ballbot_arm_description/meshes/link_forearm.stl"/>
      </geometry>
    </collision>
  </link>
  <joint name="wrist_1_joint" type="revolute">
    <origin rpy="0 -1.5707963268 0" xyz="0.112 -0.07 0"/>
    <axis xyz="0 0 1"/>
    <limit effort="30" lower="-3.14159265359" upper="3.14159265359" velocity="1.0"/>
    <parent link="forearm_link"/>
    <child link="forearm_2_wrist_link"/>
  </joint>
  <link name="forearm_2_wrist_link">
    <visual>
      <origin rpy="0 0 0" xyz="0 0 0"/>
      <geometry>
        <mesh filename="package://ballbot_arm_description/meshes/link_forearm_2_wrist.stl"/>
      </geometry>
    </visual>
    <collision>
      <origin rpy="0 0 0" xyz="0 0 0"/>
      <geometry>
        <mesh filename="package://ballbot_arm_description/meshes/link_forearm_2_wrist.stl"/>
      </geometry>
    </collision>
  </link>
  <joint name="wrist_2_joint" type="revolute">
    <origin rpy="0 -1.5707963268 0" xyz="0 0 -0.08"/>
    <axis xyz="0 0 1"/>
    <limit effort="30" lower="-1.5707963268" upper="1.5707963268" velocity="1.0"/>
    <parent link="forearm_2_wrist_link"/>
    <child link="wrist_mid_link"/>
  </joint>
  <link name="wrist_mid_link">
    <visual>
      <origin rpy="0 0 0" xyz="0 0 0"/>
      <geometry>
        <mesh filename="package://ballbot_arm_description/meshes/link_wrist_mid.stl"/>
      </geometry>
    </visual>
    <collision>
      <origin rpy="0 0 0" xyz="0 0 0"/>
      <geometry>
        <mesh filename="package://ballbot_arm_description/meshes/link_wrist_mid.stl"/>
      </geometry>
    </collision>
  </link>
  <joint name="wrist_3_joint" type="revolute">
    <origin rpy="-1.5707963268 0 0" xyz="-0.107616 0 0"/>
    <axis xyz="0 0 1"/>
    <limit effort="30" lower="-1.5707963268" upper="1.5707963268" velocity="1.0"/>
    <parent link="wrist_mid_link"/>
    <child link="wrist_2_hand_link"/>
  </joint>
  <link name="wrist_2_hand_link">
    <visual>
      <origin rpy="0 0 0" xyz="0 0 0"/>
      <geometry>
        <mesh filename="package://ballbot_arm_description/meshes/link_wrist_2_hand.stl"/>
      </geometry>
    </visual>
    <collision>
      <origin rpy="0 0 0" xyz="0 0 0"/>
      <geometry>
        <mesh filename="package://ballbot_arm_description/meshes/link_wrist_2_hand.stl"/>
      </geometry>
    </collision>
  </link>
  <!-- Right  Barrett Hand B282
      <xacro:bhand_macro name="r_bh" parent="r_wrist_2_hand_link">
         <origin xyz="0.055 0 0" rpy="0 ${PI/2} 0" />
      </xacro:bhand_macro>-->
</robot>
