<?xml version="1.0" encoding="utf-8"?>
<!-- =================================================================================== -->
<!-- |    This document was autogenerated by xacro from ballbot_left_arm.urdf.xacro    | -->
<!-- |    EDITING THIS FILE BY HAND IS NOT RECOMMENDED                                 | -->
<!-- =================================================================================== -->
<robot name="ballbot">
  <!-- CAD -->
  <material name="black">
    <color rgba="0.0 0.0 0.0 1.0"/>
  </material>
  <material name="blue">
    <color rgba="0.0 0.0 0.8 1.0"/>
  </material>
  <material name="green">
    <color rgba="0.0 0.8 0.0 1.0"/>
  </material>
  <material name="dark_grey">
    <color rgba="0.2 0.2 0.2 1.0"/>
  </material>
  <material name="grey">
    <color rgba="0.5 0.5 0.5 1.0"/>
  </material>
  <material name="light_grey">
    <color rgba="0.8 0.8 0.8 1.0"/>
  </material>
  <material name="orange">
    <color rgba="1.0 0.423529411765 0.0392156862745 1.0"/>
  </material>
  <material name="brown">
    <color rgba="0.870588235294 0.811764705882 0.764705882353 1.0"/>
  </material>
  <material name="white">
    <color rgba="1.0 1.0 1.0 1.0"/>
  </material>
  <material name="yellow">
    <color rgba="0.8 0.68 0 1"/>
  </material>
  <material name="red">
    <color rgba="1.0 0.0 0.0 1"/>
  </material>
  <material name="aluminum">
    <color rgba="0.5 0.5 0.5 1"/>
  </material>
  <!-- ros_control plugin -->
  <gazebo>
    <plugin filename="libgazebo_ros_control.so" name="gazebo_ros_control">
      <robotNamespace>/ballbot</robotNamespace>
      <robotSimType>gazebo_ros_control/DefaultRobotHWSim</robotSimType>
      <legacyModeNS>true</legacyModeNS>
    </plugin>
  </gazebo>
  <gazebo reference="BallbotBase">
    <material>Gazebo/Orange</material>
    <selfCollide>false</selfCollide>
    <static>true</static>
  </gazebo>
  <gazebo reference="Link_FakeBall">
    <material>Gazebo/Orange</material>
    <selfCollide>true</selfCollide>
    <static>true</static>
  </gazebo>
  <gazebo reference="Link_Ball">
    <material>Gazebo/Orange</material>
    <self_collide>false</self_collide>
    <static>true</static>
  </gazebo>
  <gazebo reference="Link_FakeBody">
    <material>Gazebo/Orange</material>
    <selfCollide>false</selfCollide>
    <static>true</static>
  </gazebo>
  <gazebo reference="Link_Body">
    <material>Gazebo/Yellow</material>
    <self_collide>true</self_collide>
    <static>true</static>
  </gazebo>
  <!-- Right Arm Transmissions -->
  <transmission name="RArmTran1">
    <type>transmission_interface/SimpleTransmission</type>
    <joint name="JRA1">
      <hardwareInterface>hardware_interface/EffortJointInterface</hardwareInterface>
    </joint>
    <actuator name="RArmMotor1">
      <hardwareInterface>hardware_interface/EffortJointInterface</hardwareInterface>
      <mechanicalReduction>1</mechanicalReduction>
    </actuator>
  </transmission>
  <transmission name="RArmTran2">
    <type>transmission_interface/SimpleTransmission</type>
    <joint name="JRA2">
      <hardwareInterface>hardware_interface/EffortJointInterface</hardwareInterface>
    </joint>
    <actuator name="RArmMotor2">
      <hardwareInterface>hardware_interface/EffortJointInterface</hardwareInterface>
      <mechanicalReduction>1</mechanicalReduction>
    </actuator>
  </transmission>
  <transmission name="RArmTran3">
    <type>transmission_interface/SimpleTransmission</type>
    <joint name="JRA3">
      <hardwareInterface>hardware_interface/EffortJointInterface</hardwareInterface>
    </joint>
    <actuator name="RArmMotor3">
      <hardwareInterface>hardware_interface/EffortJointInterface</hardwareInterface>
      <mechanicalReduction>1</mechanicalReduction>
    </actuator>
  </transmission>
  <transmission name="RArmTran4">
    <type>transmission_interface/SimpleTransmission</type>
    <joint name="JRA4">
      <hardwareInterface>hardware_interface/EffortJointInterface</hardwareInterface>
    </joint>
    <actuator name="RArmMotor4">
      <hardwareInterface>hardware_interface/EffortJointInterface</hardwareInterface>
      <mechanicalReduction>1</mechanicalReduction>
    </actuator>
  </transmission>
  <transmission name="RArmTran5">
    <type>transmission_interface/SimpleTransmission</type>
    <joint name="JRA5">
      <hardwareInterface>hardware_interface/EffortJointInterface</hardwareInterface>
    </joint>
    <actuator name="RArmMotor5">
      <hardwareInterface>hardware_interface/EffortJointInterface</hardwareInterface>
      <mechanicalReduction>1</mechanicalReduction>
    </actuator>
  </transmission>
  <transmission name="RArmTran6">
    <type>transmission_interface/SimpleTransmission</type>
    <joint name="JRA6">
      <hardwareInterface>hardware_interface/EffortJointInterface</hardwareInterface>
    </joint>
    <actuator name="RArmMotor6">
      <hardwareInterface>hardware_interface/EffortJointInterface</hardwareInterface>
      <mechanicalReduction>1</mechanicalReduction>
    </actuator>
  </transmission>
  <transmission name="RArmTran7">
    <type>transmission_interface/SimpleTransmission</type>
    <joint name="JRA7">
      <hardwareInterface>hardware_interface/EffortJointInterface</hardwareInterface>
    </joint>
    <actuator name="RArmMotor7">
      <hardwareInterface>hardware_interface/EffortJointInterface</hardwareInterface>
      <mechanicalReduction>1</mechanicalReduction>
    </actuator>
  </transmission>
  <!-- Left Arm Transmissions -->
  <transmission name="LArmTran1">
    <type>transmission_interface/SimpleTransmission</type>
    <joint name="JLA1">
      <hardwareInterface>hardware_interface/EffortJointInterface</hardwareInterface>
    </joint>
    <actuator name="LArmMotor1">
      <hardwareInterface>hardware_interface/EffortJointInterface</hardwareInterface>
      <mechanicalReduction>1</mechanicalReduction>
    </actuator>
  </transmission>
  <transmission name="LArmTran2">
    <type>transmission_interface/SimpleTransmission</type>
    <joint name="JLA2">
      <hardwareInterface>hardware_interface/EffortJointInterface</hardwareInterface>
    </joint>
    <actuator name="LArmMotor2">
      <hardwareInterface>hardware_interface/EffortJointInterface</hardwareInterface>
      <mechanicalReduction>1</mechanicalReduction>
    </actuator>
  </transmission>
  <transmission name="LArmTran3">
    <type>transmission_interface/SimpleTransmission</type>
    <joint name="JLA3">
      <hardwareInterface>hardware_interface/EffortJointInterface</hardwareInterface>
    </joint>
    <actuator name="LArmMotor3">
      <hardwareInterface>hardware_interface/EffortJointInterface</hardwareInterface>
      <mechanicalReduction>1</mechanicalReduction>
    </actuator>
  </transmission>
  <transmission name="LArmTran4">
    <type>transmission_interface/SimpleTransmission</type>
    <joint name="JLA4">
      <hardwareInterface>hardware_interface/EffortJointInterface</hardwareInterface>
    </joint>
    <actuator name="LArmMotor4">
      <hardwareInterface>hardware_interface/EffortJointInterface</hardwareInterface>
      <mechanicalReduction>1</mechanicalReduction>
    </actuator>
  </transmission>
  <transmission name="LArmTran5">
    <type>transmission_interface/SimpleTransmission</type>
    <joint name="JLA5">
      <hardwareInterface>hardware_interface/EffortJointInterface</hardwareInterface>
    </joint>
    <actuator name="LArmMotor5">
      <hardwareInterface>hardware_interface/EffortJointInterface</hardwareInterface>
      <mechanicalReduction>1</mechanicalReduction>
    </actuator>
  </transmission>
  <transmission name="LArmTran6">
    <type>transmission_interface/SimpleTransmission</type>
    <joint name="JLA6">
      <hardwareInterface>hardware_interface/EffortJointInterface</hardwareInterface>
    </joint>
    <actuator name="LArmMotor6">
      <hardwareInterface>hardware_interface/EffortJointInterface</hardwareInterface>
      <mechanicalReduction>1</mechanicalReduction>
    </actuator>
  </transmission>
  <transmission name="LArmTran7">
    <type>transmission_interface/SimpleTransmission</type>
    <joint name="JLA7">
      <hardwareInterface>hardware_interface/EffortJointInterface</hardwareInterface>
    </joint>
    <actuator name="LArmMotor7">
      <hardwareInterface>hardware_interface/EffortJointInterface</hardwareInterface>
      <mechanicalReduction>1</mechanicalReduction>
    </actuator>
  </transmission>
  <!--<gazebo reference="">
    <material>Gazebo/Yellow</material>
  </gazebo>

  - Right Arm 
  <gazebo reference="Link_FakeBall">
    <mu1>0.2</mu1>
    <mu2>0.2</mu1>
    <material>Gazebo/Orange</material>
  </gazebo>

  <gazebo reference="Link_Ball">
    <mu1>0.2</mu1>
    <mu2>0.2</mu1>
    <material>Gazebo/Orange</material>
  </gazebo>

  <gazebo reference="Link_FakeBody">
    <mu1>0.2</mu1>
    <mu2>0.2</mu1>
    <material>Gazebo/Orange</material>
  </gazebo>

  <gazebo reference="Link_Body">
    <mu1>0.2</mu1>
    <mu2>0.2</mu1>
    <material>Gazebo/Orange</material>
  </gazebo-->
  <!-- Used for fixing robot to Gazebo 'base_link' -->
  <link name="base_link"/>
  <!-- ====================================== -->
  <!-- Left Arm-->
  <joint name="JLA0" type="fixed">
    <origin rpy="1.5707963268 -1.5707963268 -3.14159265359" xyz="-0.00635 0.12314 0.56715"/>
    <parent link="base_link"/>
    <child link="LArm0"/>
    <axis xyz="0 0 1"/>
  </joint>
  <link name="LArm0">
    <inertial>
      <origin rpy="0 0 0" xyz="-0.00832 0.0 -0.0418"/>
      <mass value="2.367"/>
      <inertia ixx="0.00366" ixy="0.0" ixz="-0.0000208" iyy="0.00398" iyz="0.0" izz="0.00461"/>
    </inertial>
    <visual>
      <origin rpy="0 0 0" xyz="0 0 0"/>
      <geometry>
        <mesh filename="package://ballbot_arm_description/meshes/v2020_dae/link_base.dae"/>
      </geometry>
      <material name="grey"/>
    </visual>
    <collision>
      <origin rpy="0 0 0" xyz="0 0 0"/>
      <geometry>
        <mesh filename="package://ballbot_arm_description/meshes/v2020_dae/link_base.dae"/>
      </geometry>
    </collision>
  </link>
  <link name="LArm1">
    <inertial>
      <origin xyz="0.0 0.00329 0.0865"/>
      <mass value="4.181"/>
      <inertia ixx="0.0172" ixy="0.0000173" ixz="0.0" iyy="0.0170" iyz="-0.000935" izz="0.00602"/>
    </inertial>
    <visual>
      <origin rpy="0 0 0" xyz="0.0 0.0 0.0"/>
      <geometry>
        <mesh filename="package://ballbot_arm_description/meshes/v2020_dae/link_shoulder_2_base.dae"/>
      </geometry>
      <material name="brown"/>
    </visual>
    <collision>
      <origin rpy="0 0 0" xyz="0.0 0.0 -0.05525"/>
      <geometry>
        <cylinder length="0.1105" radius="0.05"/>
      </geometry>
      <material name="blue"/>
    </collision>
  </link>
  <link name="LArm2">
    <inertial>
      <origin xyz="-0.123 0.000 -0.0507"/>
      <mass value="1.832"/>
      <inertia ixx="0.00241" ixy="0.0" ixz="-0.000742" iyy="0.00559" iyz="0.0" izz="0.00563"/>
    </inertial>
    <visual>
      <origin rpy="0 0 0" xyz="0.0 0.0 0.0"/>
      <geometry>
        <mesh filename="package://ballbot_arm_description/meshes/v2020_dae/link_shoulder_2_uparm.dae"/>
      </geometry>
      <material name="grey"/>
    </visual>
    <collision>
      <origin rpy="0 0 0" xyz="0.0 0.0 -0.05525"/>
      <geometry>
        <cylinder length="0.1105" radius="0.05"/>
      </geometry>
      <material name="blue"/>
    </collision>
  </link>
  <link name="LArm3">
    <inertial>
      <origin xyz="0.0 -0.00963 0.0773"/>
      <mass value="1.821"/>
      <inertia ixx="0.00375" ixy="0.0" ixz="0.0" iyy="0.00338" iyz="0.000169" izz="0.00278"/>
    </inertial>
    <visual>
      <origin rpy="0 0 0" xyz="0.0 0.0 -0.02718"/>
      <geometry>
        <mesh filename="package://ballbot_arm_description/meshes/v2020_dae/link_upperarm.dae"/>
      </geometry>
      <material name="brown"/>
    </visual>
    <collision>
      <origin rpy="0 0 0" xyz="0.0 0.0 -0.05525"/>
      <geometry>
        <cylinder length="0.1105" radius="0.05"/>
      </geometry>
      <material name="blue"/>
    </collision>
  </link>
  <link name="LArm4">
    <inertial>
      <origin xyz="-0.0758 -0.0594 -0.0448"/>
      <mass value="1.105"/>
      <inertia ixx="0.00186" ixy="-0.000915" ixz="-0.000456" iyy="0.00276" iyz="-0.000276" izz="0.00356"/>
    </inertial>
    <visual>
      <origin rpy="0 0 0" xyz="0.0 0.0 0.0"/>
      <geometry>
        <mesh filename="package://ballbot_arm_description/meshes/v2020_dae/link_forearm.dae"/>
      </geometry>
      <material name="grey"/>
    </visual>
    <collision>
      <origin rpy="0 0 0" xyz="0.0 0.0 -0.05525"/>
      <geometry>
        <cylinder length="0.1105" radius="0.05"/>
      </geometry>
      <material name="blue"/>
    </collision>
  </link>
  <link name="LArm5">
    <inertial>
      <origin xyz="-0.00147 0.0 -0.0537"/>
      <mass value="0.973"/>
      <inertia ixx="0.00106" ixy="0.0" ixz="-0.0000188" iyy="0.00123" iyz="0.0" izz="0.00101"/>
    </inertial>
    <visual>
      <origin rpy="0 0 0" xyz="0.0 0.0 0.0"/>
      <geometry>
        <mesh filename="package://ballbot_arm_description/meshes/v2020_dae/link_forearm_2_wrist.dae"/>
      </geometry>
      <material name="brown"/>
    </visual>
    <collision>
      <origin rpy="0 0 0" xyz="0.0 0.0 0.0495"/>
      <geometry>
        <cylinder length="0.099" radius="0.0375"/>
      </geometry>
      <material name="blue"/>
    </collision>
  </link>
  <link name="LArm6">
    <inertial>
      <origin xyz="0.0947 0.00543 0.0386"/>
      <mass value="1.013"/>
      <inertia ixx="0.00106" ixy="-0.0000831" ixz="-0.000236" iyy="0.00193" iyz="-0.0000139" izz="0.00215"/>
    </inertial>
    <visual>
      <origin rpy="0 0 0" xyz="0.0 0.0 0.0"/>
      <geometry>
        <mesh filename="package://ballbot_arm_description/meshes/v2020_dae/link_wrist_mid.dae"/>
      </geometry>
      <material name="grey"/>
    </visual>
    <collision>
      <origin rpy="0 0 0" xyz="0.0 0.0 0.0495"/>
      <geometry>
        <cylinder length="0.099" radius="0.0375"/>
      </geometry>
      <material name="blue"/>
    </collision>
  </link>
  <link name="LArm7">
    <inertial>
      <origin xyz="0.0235 -0.000000178 0.0295"/>
      <mass value="0.195"/>
      <inertia ixx="0.000257" ixy="0.0" ixz="-0.0000691" iyy="0.000325" iyz="0.0" izz="0.000362"/>
    </inertial>
    <visual>
      <origin rpy="0 0 0" xyz="0.0 0.0 0.0"/>
      <geometry>
        <mesh filename="package://ballbot_arm_description/meshes/v2020_dae/link_wrist_2_hand.dae"/>
      </geometry>
      <material name="brown"/>
    </visual>
    <collision>
      <origin rpy="0 0 0" xyz="0.0 0.0 0.0495"/>
      <geometry>
        <cylinder length="0.099" radius="0.0375"/>
      </geometry>
      <material name="blue"/>
    </collision>
  </link>
  <joint name="JLA1" type="revolute">
    <origin rpy="0.0 0.0 0.0" xyz="0.0 0.0 0.0"/>
    <parent link="LArm0"/>
    <child link="LArm1"/>
    <limit effort="30.0" lower="-2.96705972839" upper="2.96705972839" velocity="3.0"/>
    <axis xyz="0 0 1"/>
    <dynamics damping="0.7" friction="0.5"/>
  </joint>
  <joint name="JLA2" type="revolute">
    <origin rpy="1.5707963705062866 -0.0 0.0" xyz="0.00000 -0.05436 0.14900"/>
    <parent link="LArm1"/>
    <child link="LArm2"/>
    <limit effort="30.0" lower="-1.5707963268" upper="0.0349065850399" velocity="3.0"/>
    <axis xyz="0 0 1"/>
    <dynamics damping="0.7" friction="0.5"/>
  </joint>
  <joint name="JLA3" type="revolute">
    <origin rpy="2.0344439357957036 1.5707962290814481 -1.1071487177940917" xyz="-0.17786 0.00000 -0.05436"/>
    <parent link="LArm2"/>
    <child link="LArm3"/>
    <limit effort="30.0" lower="-1.5707963268" upper="1.5707963268" velocity="3.0"/>
    <axis xyz="0 0 1"/>
    <dynamics damping="0.7" friction="0.5"/>
  </joint>
  <joint name="JLA4" type="revolute">
    <origin rpy="-2.3561944901923457 1.5707962635746238 2.3561944901923457" xyz="0.00000 -0.05436 0.08522"/>
    <parent link="LArm3"/>
    <child link="LArm4"/>
    <limit effort="30.0" lower="-2.79252680319" upper="0.349065850399" velocity="3.0"/>
    <axis xyz="0 0 1"/>
    <dynamics damping="0.7" friction="0.5"/>
  </joint>
  <joint name="JLA5" type="revolute">
    <origin rpy="-1.5707963268 -1.5707963268 -1.5707963268" xyz="-0.13200 -0.07000 -0.05073"/>
    <parent link="LArm4"/>
    <child link="LArm5"/>
    <limit effort="30.0" lower="-2.82743338823" upper="2.82743338823" velocity="3.0"/>
    <axis xyz="0 0 1"/>
    <dynamics damping="0.7" friction="0.5"/>
  </joint>
  <joint name="JLA6" type="revolute">
    <origin rpy="0 1.5707963268 0" xyz="-0.041150 0.0 -0.06000"/>
    <parent link="LArm5"/>
    <child link="LArm6"/>
    <limit effort="30.0" lower="-1.49599650171" upper="1.49599650171" velocity="3.0"/>
    <axis xyz="0 0 1"/>
    <dynamics damping="0.7" friction="0.5"/>
  </joint>
  <joint name="JLA7" type="revolute">
    <origin rpy="1.5707963268 0.0 0.0" xyz="0.10750 0.04650 0.041150"/>
    <parent link="LArm6"/>
    <child link="LArm7"/>
    <limit effort="30.0" lower="-1.49599650171" upper="1.49599650171" velocity="3.0"/>
    <axis xyz="0 0 1"/>
    <dynamics damping="0.7" friction="0.5"/>
  </joint>
  <link name="toolL">
    <inertial>
      <origin xyz="0.0 0.0 0.0"/>
      <mass value="0.241"/>
      <inertia ixx="0.00001" ixy="0.0" ixz="0.0" iyy="0.00001" iyz="0.0" izz="0.00001"/>
    </inertial>
  </link>
  <joint name="LArm7-toolL" type="fixed">
    <origin rpy="0 1.5707963268 0" xyz="0.055 0 0.04065"/>
    <axis xyz="0 0 1"/>
    <parent link="LArm7"/>
    <child link="toolL"/>
  </joint>
</robot>
