<?xml version="1.0" ?>
<!-- =================================================================================== -->
<!-- |    This document was autogenerated by xacro from ballbot_dual_arm_wBarrettHand.urdf.xacro | -->
<!-- |    EDITING THIS FILE BY HAND IS NOT RECOMMENDED                                 | -->
<!-- =================================================================================== -->
<robot name="ballbotDualArm" xmlns:xacro="http://ros.org/wiki/xacro">
  <material name="black">
    <color rgba="0.0 0.0 0.0 1.0"/>
  </material>
  <material name="blue">
    <color rgba="0.0 0.0 0.8 1.0"/>
  </material>
  <material name="green">
    <color rgba="0.0 0.8 0.0 1.0"/>
  </material>
  <material name="grey">
    <color rgba="0.5 0.5 0.5 1.0"/>
  </material>
  <material name="orange">
    <color rgba="1.0 0.423529411765 0.0392156862745 1.0"/>
  </material>
  <material name="brown">
    <color rgba="0.870588235294 0.811764705882 0.764705882353 1.0"/>
  </material>
  <material name="white">
    <color rgba="1.0 1.0 1.0 1.0"/>
  </material>
  <material name="yellow">
    <color rgba="0.8 0.68 0 1"/>
  </material>
  <material name="red">
    <color rgba="1.0 0.0 0.0 1"/>
  </material>
  <!--- Notes
 Units used:
 - Length: m
 - Mass: kg
 - Inertia: kg*m^2
-->
  <!-- ballbot_arm_left -->
  <!-- Use of macros to assemble the robot -->
  <!-- Use of macros to assemble the robot -->
  <!-- Dummy Link to World -->
  <link name="base_link"/>
  <joint name="fixed" type="fixed">
    <origin rpy="0 0 0" xyz="0 0 0"/>
    <parent link="base_link"/>
    <child link="ballbot_body_link"/>
  </joint>
  <link name="ballbot_body_link">
    <visual>
      <origin rpy="0 0 2.09439510239" xyz="0 0 0"/>
      <geometry>
        <mesh filename="package://ballbot_arm_description/meshes/ballbot_body_wcover.stl"/>
      </geometry>
      <material name="yellow"/>
    </visual>
    <collision>
      <origin rpy="0 0 0" xyz="0 0 0.7025"/>
      <geometry>
        <cylinder length="1.405" radius="0.184"/>
      </geometry>
    </collision>
    <inertial>
      <origin rpy="0 0 0" xyz="0 0 0.762"/>
      <mass value="67.58"/>
      <inertia ixx="15.889" ixy="0.0" ixz="0.00002075" iyy="15.889" iyz="0.0" izz="0.004605"/>
    </inertial>
  </link>
  <!-- 7DoF Right Arm -->
  <joint name="joint_body_2_right_arm_base" type="fixed">
    <origin rpy="0 0 1.57079632679" xyz="-0.00635 -0.120135 1.19"/>
    <axis xyz="0 0 1"/>
    <parent link="base_link"/>
    <child link="r_arm_base_link"/>
  </joint>
  <link name="r_arm_base_link">
    <visual>
      <origin rpy="0 1.57079632679 3.14159265359" xyz="0 0 0"/>
      <geometry>
        <mesh filename="package://ballbot_arm_description/meshes/link_base.stl"/>
      </geometry>
      <material name="grey"/>
    </visual>
    <collision>
      <origin rpy="0 1.57079632679 3.14159265359" xyz="0 0 0"/>
      <geometry>
        <mesh filename="package://ballbot_arm_description/meshes/link_base.stl"/>
      </geometry>
    </collision>
    <inertial>
      <origin rpy="0 0 0" xyz="0 0 0"/>
      <mass value="2.367"/>
      <inertia ixx="0.003661" ixy="0.0" ixz="0.00002075" iyy="0.003977" iyz="0.0" izz="0.004605"/>
    </inertial>
  </link>
  <joint name="r_JOINT1" type="continuous">
    <origin rpy="1.57079632679 0 -1.57079632679" xyz="0 0 0"/>
    <axis xyz="0 0 1"/>
    <limit effort="5.0" lower="-6.28318530718" upper="6.28318530718" velocity="2.0"/>
    <parent link="r_arm_base_link"/>
    <child link="r_shoulder_2_base_link"/>
    <dynamics damping="0.7"/>
  </joint>
  <link name="r_shoulder_2_base_link">
    <visual>
      <origin rpy="0 1.57079632679 3.14159265359" xyz="0 0 0"/>
      <geometry>
        <mesh filename="package://ballbot_arm_description/meshes/link_shoulder_2_base.stl"/>
      </geometry>
      <material name="blue"/>
    </visual>
    <collision>
      <origin rpy="0 1.57079632679 3.14159265359" xyz="0 0 0"/>
      <geometry>
        <mesh filename="package://ballbot_arm_description/meshes/link_shoulder_2_base.stl"/>
      </geometry>
    </collision>
    <inertial>
      <origin rpy="0 0 0" xyz="0 0 0"/>
      <mass value="4.322"/>
      <inertia ixx="0.015600" ixy="0.000000994" ixz="0.000002133" iyy="0.15800" iyz="-0.0008068" izz="0.005718"/>
    </inertial>
  </link>
  <joint name="r_JOINT2" type="revolute">
    <origin rpy="0 -1.57079632679 0" xyz="0 0 0.15"/>
    <axis xyz="0 0 1"/>
    <limit effort="5.0" lower="-1.57079632679" upper="1.57079632679" velocity="2.0"/>
    <parent link="r_shoulder_2_base_link"/>
    <child link="r_shoulder_2_uparm_link"/>
    <dynamics damping="0.7"/>
  </joint>
  <link name="r_shoulder_2_uparm_link">
    <visual>
      <origin rpy="3.14159265359 0 1.57079632679" xyz="0 0 0"/>
      <geometry>
        <mesh filename="package://ballbot_arm_description/meshes/link_shoulder_2_uparm.stl"/>
      </geometry>
      <material name="grey"/>
    </visual>
    <collision>
      <origin rpy="3.14159265359 0 1.57079632679" xyz="0 0 0"/>
      <geometry>
        <mesh filename="package://ballbot_arm_description/meshes/link_shoulder_2_uparm.stl"/>
      </geometry>
    </collision>
    <inertial>
      <origin rpy="0 0 0" xyz="0 0 0"/>
      <mass value="1.888"/>
      <inertia ixx="0.002866" ixy="0.0" ixz="0.0002159" iyy="0.005072" iyz="0.0" izz="0.004689"/>
    </inertial>
  </link>
  <joint name="r_JOINT3" type="continuous">
    <origin rpy="1.57079632679 0 0" xyz="0 -0.150683 0"/>
    <axis xyz="0 0 1"/>
    <limit effort="5.0" lower="0" upper="6.28318530718" velocity="2.0"/>
    <parent link="r_shoulder_2_uparm_link"/>
    <child link="r_uparm_link"/>
    <dynamics damping="0.7"/>
  </joint>
  <link name="r_uparm_link">
    <visual>
      <origin rpy="3.14159265359 0 1.57079632679" xyz="0 0 0"/>
      <geometry>
        <mesh filename="package://ballbot_arm_description/meshes/link_uparm.stl"/>
      </geometry>
      <material name="blue"/>
    </visual>
    <collision>
      <origin rpy="3.14159265359 0 1.57079632679" xyz="0 0 0"/>
      <geometry>
        <mesh filename="package://ballbot_arm_description/meshes/link_uparm.stl"/>
      </geometry>
    </collision>
    <inertial>
      <origin rpy="0 0 0" xyz="0 0 0"/>
      <mass value="1.821"/>
      <inertia ixx="0.005026" ixy="0.0" ixz="0.0" iyy="0.005136" iyz="0.0004929" izz="0.002311"/>
    </inertial>
  </link>
  <joint name="r_JOINT4" type="revolute">
    <origin rpy="0 1.57079632679 0" xyz="0 0 0.112431"/>
    <axis xyz="0 0 1"/>
    <limit effort="5.0" lower="-0.349065850399" upper="2.26892802759" velocity="2.0"/>
    <parent link="r_uparm_link"/>
    <child link="r_forearm_r_link"/>
    <dynamics damping="0.7"/>
  </joint>
  <link name="r_forearm_r_link">
    <visual>
      <origin rpy="3.14159265359 0 -1.57079632679" xyz="0 0 0"/>
      <geometry>
        <mesh filename="package://ballbot_arm_description/meshes/link_forearm_r.stl"/>
      </geometry>
      <material name="grey"/>
    </visual>
    <collision>
      <origin rpy="3.14159265359 0 -1.57079632679" xyz="0 0 0"/>
      <geometry>
        <mesh filename="package://ballbot_arm_description/meshes/link_forearm_r.stl"/>
      </geometry>
    </collision>
    <inertial>
      <origin rpy="0 0 0" xyz="0 0 0"/>
      <mass value="1.820"/>
      <inertia ixx="0.003260" ixy="0.0007391" ixz="-0.0001047" iyy="0.003214" iyz="-0.00005031" izz="0.003893"/>
    </inertial>
  </link>
  <joint name="r_JOINT5" type="continuous">
    <origin rpy="3.14159265359 -1.57079632679 0.0" xyz="-0.112 0.07 0"/>
    <axis xyz="0 0 1"/>
    <limit effort="5.0" lower="-6.28318530718" upper="6.28318530718" velocity="2.0"/>
    <parent link="r_forearm_r_link"/>
    <child link="r_forearm_2_wrist_link"/>
    <dynamics damping="0.7"/>
  </joint>
  <link name="r_forearm_2_wrist_link">
    <visual>
      <origin rpy="0 0 -1.57079632679" xyz="0 0 0"/>
      <geometry>
        <mesh filename="package://ballbot_arm_description/meshes/link_forearm_2_wrist.stl"/>
      </geometry>
      <material name="blue"/>
    </visual>
    <collision>
      <origin rpy="0 0 -1.57079632679" xyz="0 0 0"/>
      <geometry>
        <mesh filename="package://ballbot_arm_description/meshes/link_forearm_2_wrist.stl"/>
      </geometry>
    </collision>
    <inertial>
      <origin rpy="0 0 0" xyz="0 0 0"/>
      <mass value="0.973"/>
      <inertia ixx="0.001063" ixy="0" ixz="-0.00004093" iyy="0.001178" iyz="0" izz="0.0009625"/>
    </inertial>
  </link>
  <joint name="r_JOINT6" type="revolute">
    <origin rpy="0 1.57079632679 1.57079632679" xyz="0 0 -0.08"/>
    <axis xyz="0 0 1"/>
    <limit effort="5.0" lower="-1.57079632679" upper="1.57079632679" velocity="2.0"/>
    <parent link="r_forearm_2_wrist_link"/>
    <child link="r_wrist_mid_link"/>
    <dynamics damping="0.7"/>
  </joint>
  <link name="r_wrist_mid_link">
    <visual>
      <origin rpy="0 0 3.14159265359" xyz="0 0 0"/>
      <geometry>
        <mesh filename="package://ballbot_arm_description/meshes/link_wrist_mid.stl"/>
      </geometry>
      <material name="grey"/>
    </visual>
    <collision>
      <origin rpy="0 0 3.14159265359" xyz="0 0 0"/>
      <geometry>
        <mesh filename="package://ballbot_arm_description/meshes/link_wrist_mid.stl"/>
      </geometry>
    </collision>
    <inertial>
      <origin rpy="0 0 0" xyz="0 0 0"/>
      <mass value="1.013"/>
      <inertia ixx="0.0009954" ixy="0.0001979" ixz="0.00008468" iyy="0.002233" iyz="-0.00001389" izz="0.002236"/>
    </inertial>
  </link>
  <joint name="r_JOINT7" type="revolute">
    <origin rpy="1.57079632679 3.14159265359 0" xyz="0.107616 0.005 0"/>
    <axis xyz="0 0 1"/>
    <limit effort="5.0" lower="-1.57079632679" upper="1.57079632679" velocity="2.0"/>
    <parent link="r_wrist_mid_link"/>
    <child link="r_wrist_2_hand_link"/>
    <dynamics damping="0.7"/>
  </joint>
  <link name="r_wrist_2_hand_link">
    <visual>
      <origin rpy="0 0 0" xyz="0 0 0"/>
      <geometry>
        <mesh filename="package://ballbot_arm_description/meshes/link_wrist_2_hand.stl"/>
      </geometry>
      <material name="blue"/>
    </visual>
    <collision>
      <origin rpy="0 0 0" xyz="0 0 0"/>
      <geometry>
        <mesh filename="package://ballbot_arm_description/meshes/link_wrist_2_hand.stl"/>
      </geometry>
    </collision>
    <inertial>
      <origin rpy="0 0 0" xyz="0 0 0"/>
      <mass value="0.9524"/>
      <inertia ixx="0.0009135" ixy="0.0" ixz="0.00004441" iyy="0.001068" iyz="0.0" izz="0.0009050"/>
    </inertial>
  </link>
  <joint name="r_bh_base_joint" type="fixed">
    <origin rpy="0 -1.57079632679 0" xyz="-0.055 0 0"/>
    <parent link="r_wrist_2_hand_link"/>
    <child link="r_bh_base_link"/>
  </joint>
  <!-- HAND BASE_LINK (RED) -->
  <link name="r_bh_base_link">
    <inertial>
      <mass value="1.0"/>
      <origin xyz="0 0 0"/>
      <inertia ixx="1.0" ixy="0.0" ixz="0.0" iyy="1.0" iyz="0.0" izz="1.0"/>
    </inertial>
    <visual>
      <origin rpy="0 0 0" xyz="0 0 0"/>
      <geometry>
        <mesh filename="package://barrett_hand_description/meshes/palm_280.dae"/>
      </geometry>
      <material name="Grey">
        <color rgba="0.75 0.75 0.75 1.0"/>
      </material>
    </visual>
    <collision>
      <origin rpy="0 0 0 " xyz="0 0 0"/>
      <geometry>
        <mesh filename="package://barrett_hand_description/meshes/palm_280.dae"/>
      </geometry>
      <contact_coefficients kd="1.0" kp="1000.0" mu="0"/>
    </collision>
  </link>
  <!-- finger 3 -->
  <!-- finger 32 link -->
  <link name="r_bh_finger_32_link">
    <inertial>
      <mass value="0.1"/>
      <origin rpy="0 0 0" xyz="0 0 0"/>
      <inertia ixx="0.01" ixy="0" ixz="0" iyy="0.01" iyz="0" izz="0.01"/>
    </inertial>
    <visual>
      <origin rpy="0 0 0" xyz="0 0 0"/>
      <geometry>
        <mesh filename="package://barrett_hand_description/meshes/finger.dae"/>
      </geometry>
      <material name="Blue"/>
    </visual>
    <collision>
      <origin rpy="0 0 0" xyz="0 0 0"/>
      <geometry>
        <mesh filename="package://barrett_hand_description/meshes/finger.dae"/>
      </geometry>
      <contact_coefficients kd="1.0" kp="1000.0" mu="0"/>
    </collision>
  </link>
  <!-- joint between BH_finger_31_link and BH_finger_32_link -->
  <joint name="r_bh_j32_joint" type="revolute">
    <parent link="r_bh_base_link"/>
    <child link="r_bh_finger_32_link"/>
    <origin rpy="1.5708 1.5708 1.5708" xyz="0 -0.05 0.0754"/>
    <axis xyz="0 0 -1"/>
    <limit effort="30.0" lower="0.0" upper="2.44" velocity="2.0"/>
    <dynamics damping="100.0" friction="1.0"/>
  </joint>
  <transmission name="r_bh_j32_transmission">
    <type>transmission_interface/SimpleTransmission</type>
    <joint name="r_bh_j32_joint">
      <hardwareInterface>PositionJointInterface</hardwareInterface>
    </joint>
    <actuator name="r_bh_j32">
      <hardwareInterface>PositionJointInterface</hardwareInterface>
      <mechanicalReduction>1</mechanicalReduction>
      <motorTorqueConstant>1</motorTorqueConstant>
    </actuator>
  </transmission>
  <!-- finger 33 link -->
  <link name="r_bh_finger_33_link">
    <inertial>
      <mass value="0.1"/>
      <origin rpy="0 0 0" xyz="0 0 0"/>
      <inertia ixx="0.01" ixy="0" ixz="0" iyy="0.01" iyz="0" izz="0.01"/>
    </inertial>
    <visual>
      <origin rpy="0 0 0" xyz="0 0 0"/>
      <geometry>
        <mesh filename="package://barrett_hand_description/meshes/finger_tip.dae"/>
      </geometry>
      <material name="Blue"/>
    </visual>
    <collision>
      <origin rpy="0 0 0" xyz="0 0 0"/>
      <geometry>
        <mesh filename="package://barrett_hand_description/meshes/finger_tip.dae"/>
      </geometry>
      <contact_coefficients kd="1.0" kp="1000.0" mu="0"/>
    </collision>
  </link>
  <!-- joint between BH_finger_32_link and BH_finger_33_link -->
  <joint name="r_bh_j33_joint" type="revolute">
    <parent link="r_bh_finger_32_link"/>
    <child link="r_bh_finger_33_link"/>
    <origin rpy="0 0 0" xyz="-0.069936 0.003 0"/>
    <axis xyz="0 0 -1"/>
    <mimic joint="r_bh_j32_joint" multiplier="0.344262295082"/>
    <limit effort="30.0" lower="0.0" upper="0.84" velocity="2.0"/>
    <dynamics damping="100.0" friction="1.0"/>
  </joint>
  <transmission name="r_bh_j33_transmission">
    <type>transmission_interface/SimpleTransmission</type>
    <joint name="r_bh_j33_joint">
      <hardwareInterface>PositionJointInterface</hardwareInterface>
    </joint>
    <actuator name="r_bh_j33">
      <hardwareInterface>PositionJointInterface</hardwareInterface>
      <mechanicalReduction>1</mechanicalReduction>
      <motorTorqueConstant>1</motorTorqueConstant>
    </actuator>
  </transmission>
  <!-- finger 1 -->
  <!-- finger 11 link -->
  <link name="r_bh_finger_11_link">
    <inertial>
      <mass value="0.1"/>
      <origin rpy="0 0 0" xyz="-0.046 0 0"/>
      <inertia ixx="0.01" ixy="0" ixz="0" iyy="0.01" iyz="0" izz="0.01"/>
    </inertial>
    <visual>
      <origin rpy="0 0 0" xyz="0 0 0"/>
      <geometry>
        <mesh filename="package://barrett_hand_description/meshes/knuckle.dae"/>
      </geometry>
      <material name="Green"/>
    </visual>
    <collision>
      <origin rpy="0 0 0" xyz="0 0 0"/>
      <geometry>
        <mesh filename="package://barrett_hand_description/meshes/knuckle.dae"/>
      </geometry>
    </collision>
  </link>
  <!-- joint between BH_palm_link and BH_finger_11_link -->
  <joint name="r_bh_j11_joint" type="revolute">
    <parent link="r_bh_base_link"/>
    <child link="r_bh_finger_11_link"/>
    <origin rpy="0 0 -1.5708" xyz="0.025 0 0.0415"/>
    <axis xyz="0 0 -1"/>
    <limit effort="30.0" lower="0" upper="3.1416" velocity="2.0"/>
    <dynamics damping="100.0" friction="1.0"/>
  </joint>
  <transmission name="r_bh_j11_transmission">
    <type>transmission_interface/SimpleTransmission</type>
    <joint name="r_bh_j11_joint">
      <hardwareInterface>PositionJointInterface</hardwareInterface>
    </joint>
    <actuator name="r_bh_j11">
      <hardwareInterface>PositionJointInterface</hardwareInterface>
      <mechanicalReduction>1</mechanicalReduction>
      <motorTorqueConstant>1</motorTorqueConstant>
    </actuator>
  </transmission>
  <!-- finger 12 link -->
  <link name="r_bh_finger_12_link">
    <inertial>
      <mass value="0.1"/>
      <origin rpy="0 0 0" xyz="0 0 0"/>
      <inertia ixx="0.01" ixy="0" ixz="0" iyy="0.01" iyz="0" izz="0.01"/>
    </inertial>
    <visual>
      <origin rpy="0 0 0" xyz="0 0 0"/>
      <geometry>
        <mesh filename="package://barrett_hand_description/meshes/finger.dae"/>
      </geometry>
      <material name="Blue"/>
    </visual>
    <collision>
      <origin rpy="0 0 0" xyz="0 0 0"/>
      <geometry>
        <mesh filename="package://barrett_hand_description/meshes/finger.dae"/>
      </geometry>
      <contact_coefficients kd="1.0" kp="1000.0" mu="0"/>
    </collision>
  </link>
  <!-- joint between BH_finger_11_link and BH_finger_12_link -->
  <joint name="r_bh_j12_joint" type="revolute">
    <parent link="r_bh_finger_11_link"/>
    <child link="r_bh_finger_12_link"/>
    <origin rpy="1.5708 1.5708 0" xyz="-0.05 0 0.0339"/>
    <axis xyz="0 0 -1"/>
    <limit effort="30.0" lower="0.0" upper="2.44" velocity="2.0"/>
    <dynamics damping="100.0" friction="1.0"/>
  </joint>
  <transmission name="r_bh_j12_transmission">
    <type>transmission_interface/SimpleTransmission</type>
    <joint name="r_bh_j12_joint">
      <hardwareInterface>PositionJointInterface</hardwareInterface>
    </joint>
    <actuator name="r_bh_j12">
      <hardwareInterface>PositionJointInterface</hardwareInterface>
      <mechanicalReduction>1</mechanicalReduction>
      <motorTorqueConstant>1</motorTorqueConstant>
    </actuator>
  </transmission>
  <!-- finger 13 link -->
  <link name="r_bh_finger_13_link">
    <inertial>
      <mass value="0.1"/>
      <origin rpy="0 0 0" xyz="0 0 0"/>
      <inertia ixx="0.01" ixy="0" ixz="0" iyy="0.01" iyz="0" izz="0.01"/>
    </inertial>
    <visual>
      <origin rpy="0 0 0" xyz="0 0 0"/>
      <geometry>
        <mesh filename="package://barrett_hand_description/meshes/finger_tip.dae"/>
      </geometry>
      <material name="Blue"/>
    </visual>
    <collision>
      <origin rpy="0 0 0" xyz="0 0 0"/>
      <geometry>
        <mesh filename="package://barrett_hand_description/meshes/finger_tip.dae"/>
      </geometry>
      <contact_coefficients kd="1.0" kp="1000.0" mu="0"/>
    </collision>
  </link>
  <!-- joint between BH_finger_12_link and BH_finger_13_link -->
  <joint name="r_bh_j13_joint" type="revolute">
    <parent link="r_bh_finger_12_link"/>
    <child link="r_bh_finger_13_link"/>
    <origin rpy="0 0 0" xyz="-0.069936 0.003 0"/>
    <axis xyz="0 0 -1"/>
    <mimic joint="r_bh_j12_joint" multiplier="0.344262295082"/>
    <limit effort="30.0" lower="0.0" upper="0.84" velocity="2.0"/>
    <dynamics damping="100.0" friction="1.0"/>
  </joint>
  <transmission name="r_bh_j13_transmission">
    <type>transmission_interface/SimpleTransmission</type>
    <joint name="r_bh_j13_joint">
      <hardwareInterface>PositionJointInterface</hardwareInterface>
    </joint>
    <actuator name="r_bh_j13">
      <hardwareInterface>PositionJointInterface</hardwareInterface>
      <mechanicalReduction>1</mechanicalReduction>
      <motorTorqueConstant>1</motorTorqueConstant>
    </actuator>
  </transmission>
  <!-- finger 2 -->
  <!-- finger 21 link -->
  <link name="r_bh_finger_21_link">
    <inertial>
      <mass value="0.1"/>
      <origin rpy="0 0 0" xyz="-0.046 0 0"/>
      <inertia ixx="0.01" ixy="0" ixz="0" iyy="0.01" iyz="0" izz="0.01"/>
    </inertial>
    <visual>
      <origin rpy="0 0 0" xyz="0 0 0"/>
      <geometry>
        <mesh filename="package://barrett_hand_description/meshes/knuckle.dae"/>
      </geometry>
      <material name="Green"/>
    </visual>
    <collision>
      <origin rpy="0 0 0" xyz="0 0 0"/>
      <geometry>
        <mesh filename="package://barrett_hand_description/meshes/knuckle.dae"/>
      </geometry>
    </collision>
  </link>
  <!-- joint between BH_palm_link and BH_finger_21_link -->
  <joint name="r_bh_j21_joint" type="revolute">
    <parent link="r_bh_base_link"/>
    <child link="r_bh_finger_21_link"/>
    <origin rpy="0 0 -1.5708" xyz="-0.025 0 0.0415"/>
    <axis xyz="0 0 1"/>
    <mimic joint="r_bh_j11_joint" multiplier="1"/>
    <limit effort="30.0" lower="0" upper="3.1416" velocity="2.0"/>
    <dynamics damping="100.0" friction="1.0"/>
  </joint>
  <transmission name="r_bh_j21_transmission">
    <type>transmission_interface/SimpleTransmission</type>
    <joint name="r_bh_j21_joint">
      <hardwareInterface>PositionJointInterface</hardwareInterface>
    </joint>
    <actuator name="r_bh_j21">
      <hardwareInterface>PositionJointInterface</hardwareInterface>
      <mechanicalReduction>1</mechanicalReduction>
      <motorTorqueConstant>1</motorTorqueConstant>
    </actuator>
  </transmission>
  <!-- finger 12 link -->
  <link name="r_bh_finger_22_link">
    <inertial>
      <mass value="0.1"/>
      <origin rpy="0 0 0" xyz="0 0 0"/>
      <inertia ixx="0.01" ixy="0" ixz="0" iyy="0.01" iyz="0" izz="0.01"/>
    </inertial>
    <visual>
      <origin rpy="0 0 0" xyz="0 0 0"/>
      <geometry>
        <mesh filename="package://barrett_hand_description/meshes/finger.dae"/>
      </geometry>
      <material name="Blue"/>
    </visual>
    <collision>
      <origin rpy="0 0 0" xyz="0 0 0"/>
      <geometry>
        <mesh filename="package://barrett_hand_description/meshes/finger.dae"/>
      </geometry>
      <contact_coefficients kd="1.0" kp="1000.0" mu="0"/>
    </collision>
  </link>
  <!-- joint between BH_finger_21_link and BH_finger_22_link -->
  <joint name="r_bh_j22_joint" type="revolute">
    <parent link="r_bh_finger_21_link"/>
    <child link="r_bh_finger_22_link"/>
    <origin rpy="1.5708 1.5708 0" xyz="-0.05 0 0.0339"/>
    <axis xyz="0 0 -1"/>
    <limit effort="30.0" lower="0.0" upper="2.44" velocity="2.0"/>
    <dynamics damping="100.0" friction="1.0"/>
  </joint>
  <transmission name="r_bh_j22_transmission">
    <type>transmission_interface/SimpleTransmission</type>
    <joint name="r_bh_j22_joint">
      <hardwareInterface>PositionJointInterface</hardwareInterface>
    </joint>
    <actuator name="r_bh_j22">
      <hardwareInterface>PositionJointInterface</hardwareInterface>
      <mechanicalReduction>1</mechanicalReduction>
      <motorTorqueConstant>1</motorTorqueConstant>
    </actuator>
  </transmission>
  <!-- finger 23 link -->
  <link name="r_bh_finger_23_link">
    <inertial>
      <mass value="0.1"/>
      <origin rpy="0 0 0" xyz="0 0 0"/>
      <inertia ixx="0.01" ixy="0" ixz="0" iyy="0.01" iyz="0" izz="0.01"/>
    </inertial>
    <visual>
      <origin rpy="0 0 0" xyz="0 0 0"/>
      <geometry>
        <mesh filename="package://barrett_hand_description/meshes/finger_tip.dae"/>
      </geometry>
      <material name="Blue"/>
    </visual>
    <collision>
      <origin rpy="0 0 0" xyz="0 0 0"/>
      <geometry>
        <mesh filename="package://barrett_hand_description/meshes/finger_tip.dae"/>
      </geometry>
      <contact_coefficients kd="1.0" kp="1000.0" mu="0"/>
    </collision>
  </link>
  <!-- joint between BH_finger_22_link and BH_finger_23_link -->
  <joint name="r_bh_j23_joint" type="revolute">
    <parent link="r_bh_finger_22_link"/>
    <child link="r_bh_finger_23_link"/>
    <origin rpy="0 0 0" xyz="-0.069936 0.003 0"/>
    <axis xyz="0 0 -1"/>
    <mimic joint="r_bh_j22_joint" multiplier="0.344262295082"/>
    <limit effort="30.0" lower="0.0" upper="0.84" velocity="2.0"/>
    <dynamics damping="100.0" friction="1.0"/>
  </joint>
  <transmission name="r_bh_j23_transmission">
    <type>transmission_interface/SimpleTransmission</type>
    <joint name="r_bh_j23_joint">
      <hardwareInterface>PositionJointInterface</hardwareInterface>
    </joint>
    <actuator name="r_bh_j23">
      <hardwareInterface>PositionJointInterface</hardwareInterface>
      <mechanicalReduction>1</mechanicalReduction>
      <motorTorqueConstant>1</motorTorqueConstant>
    </actuator>
  </transmission>
  <gazebo>
    <plugin filename="libgazebo_mimic_plugin.so" name="mimic_plugin">
      <joint>r_bh_j11_joint</joint>
      <mimicJoint>r_bh_j21_joint</mimicJoint>
      <multiplier>1</multiplier>
    </plugin>
  </gazebo>
  <gazebo>
    <plugin filename="libgazebo_mimic_plugin.so" name="mimic_plugin">
      <joint>r_bh_j12_joint</joint>
      <mimicJoint>r_bh_j13_joint</mimicJoint>
      <multiplier>0.344</multiplier>
    </plugin>
  </gazebo>
  <gazebo>
    <plugin filename="libgazebo_mimic_plugin.so" name="mimic_plugin">
      <joint>r_bh_j22_joint</joint>
      <mimicJoint>r_bh_j23_joint</mimicJoint>
      <multiplier>0.344</multiplier>
    </plugin>
  </gazebo>
  <gazebo>
    <plugin filename="libgazebo_mimic_plugin.so" name="mimic_plugin">
      <joint>r_bh_j32_joint</joint>
      <mimicJoint>r_bh_j33_joint</mimicJoint>
      <multiplier>0.344</multiplier>
    </plugin>
  </gazebo>
  <gazebo reference="r_bh_base_link">
    <material>Gazebo/White</material>
    <turnGravityOff>False</turnGravityOff>
  </gazebo>
  <gazebo reference="r_bh_finger_31_link">
    <material>Gazebo/Grey</material>
    <turnGravityOff>False</turnGravityOff>
  </gazebo>
  <gazebo reference="r_bh_finger_32_link">
    <material>Gazebo/Grey</material>
    <turnGravityOff>False</turnGravityOff>
  </gazebo>
  <gazebo reference="r_bh_finger_33_link">
    <material>Gazebo/Grey</material>
    <turnGravityOff>False</turnGravityOff>
  </gazebo>
  <gazebo reference="r_bh_finger_11_link">
    <material>Gazebo/Grey</material>
    <turnGravityOff>False</turnGravityOff>
  </gazebo>
  <gazebo reference="r_bh_finger_12_link">
    <material>Gazebo/Grey</material>
    <turnGravityOff>False</turnGravityOff>
  </gazebo>
  <gazebo reference="r_bh_finger_13_link">
    <material>Gazebo/Grey</material>
    <turnGravityOff>False</turnGravityOff>
  </gazebo>
  <gazebo reference="r_bh_finger_21_link">
    <material>Gazebo/Grey</material>
    <turnGravityOff>False</turnGravityOff>
  </gazebo>
  <gazebo reference="r_bh_finger_22_link">
    <material>Gazebo/Grey</material>
    <turnGravityOff>False</turnGravityOff>
  </gazebo>
  <gazebo reference="r_bh_finger_23_link">
    <material>Gazebo/Grey</material>
    <turnGravityOff>False</turnGravityOff>
  </gazebo>
  <!-- Imaginary joints for transform from tactile sensors -->
  <!-- Radian value obtained from graspit description of 40 degrees -->
  <!-- <joint name="${name}_finger_14_joint" type="fixed">
			<parent link="${name}_finger_13_link"/>
			<child link="${name}_finger_14_link"/>
			<origin xyz="0 0 0" rpy="0 0 0.698132" />
		</joint>
		<link name="${name}_finger_14_link"/>

		<joint name="${name}_finger_24_joint" type="fixed">
			<parent link="${name}_finger_23_link"/>
			<child link="${name}_finger_24_link"/>
			<origin xyz="0 0 0" rpy="0 0 0.698132" />
		</joint>
		<link name="${name}_finger_24_link"/>

		<joint name="${name}_finger_34_joint" type="fixed">
			<parent link="${name}_finger_33_link"/>
			<child link="${name}_finger_34_link"/>
			<origin xyz="0 0 0" rpy="0 0 0.698132" />
		</joint>
		<link name="${name}_finger_34_link"/> -->
  <!-- Auto generated tactile sensor links -->
  <!-- <xacro:bh_tactile name="bh"/> -->
  <!-- 7DoF Left Arm -->
  <joint name="joint_body_2_left_arm_base" type="fixed">
    <origin rpy="0 0 -1.57079632679" xyz="-0.00635 0.120135 1.19"/>
    <axis xyz="0 0 1"/>
    <parent link="base_link"/>
    <child link="l_arm_base_link"/>
  </joint>
  <link name="l_arm_base_link">
    <visual>
      <origin rpy="0 1.57079632679 3.14159265359" xyz="0 0 0"/>
      <geometry>
        <mesh filename="package://ballbot_arm_description/meshes/link_base.stl"/>
      </geometry>
      <material name="grey"/>
    </visual>
    <collision>
      <origin rpy="0 1.57079632679 3.14159265359" xyz="0 0 0"/>
      <geometry>
        <mesh filename="package://ballbot_arm_description/meshes/link_base.stl"/>
      </geometry>
    </collision>
    <inertial>
      <origin rpy="0 0 0" xyz="0 0 0"/>
      <mass value="2.367"/>
      <inertia ixx="0.003661" ixy="0.0" ixz="0.00002075" iyy="0.003977" iyz="0.0" izz="0.004605"/>
    </inertial>
  </link>
  <joint name="l_JOINT1" type="continuous">
    <origin rpy="1.57079632679 3.14159265359 -1.57079632679" xyz="0 0 0"/>
    <axis xyz="0 0 1"/>
    <limit effort="5.0" lower="-6.28318530718" upper="6.28318530718" velocity="2.0"/>
    <parent link="l_arm_base_link"/>
    <child link="l_shoulder_2_base_link"/>
    <dynamics damping="0.7"/>
  </joint>
  <link name="l_shoulder_2_base_link">
    <visual>
      <origin rpy="0 1.57079632679 3.14159265359" xyz="0 0 0"/>
      <geometry>
        <mesh filename="package://ballbot_arm_description/meshes/link_shoulder_2_base.stl"/>
      </geometry>
      <material name="blue"/>
    </visual>
    <collision>
      <origin rpy="0 1.57079632679 3.14159265359" xyz="0 0 0"/>
      <geometry>
        <mesh filename="package://ballbot_arm_description/meshes/link_shoulder_2_base.stl"/>
      </geometry>
    </collision>
    <inertial>
      <origin rpy="0 0 0" xyz="0 0 0"/>
      <mass value="4.322"/>
      <inertia ixx="0.015600" ixy="0.000000994" ixz="0.000002133" iyy="0.15800" iyz="-0.0008068" izz="0.005718"/>
    </inertial>
  </link>
  <joint name="l_JOINT2" type="revolute">
    <origin rpy="0 -1.57079632679 0" xyz="0 0 0.15"/>
    <axis xyz="0 0 1"/>
    <limit effort="5.0" lower="-1.57079632679" upper="1.57079632679" velocity="2.0"/>
    <parent link="l_shoulder_2_base_link"/>
    <child link="l_shoulder_2_uparm_link"/>
    <dynamics damping="0.7"/>
  </joint>
  <link name="l_shoulder_2_uparm_link">
    <visual>
      <origin rpy="3.14159265359 0 -1.57079632679" xyz="0 0 0"/>
      <geometry>
        <mesh filename="package://ballbot_arm_description/meshes/link_shoulder_2_uparm.stl"/>
      </geometry>
      <material name="grey"/>
    </visual>
    <collision>
      <origin rpy="3.14159265359 0 -1.57079632679" xyz="0 0 0"/>
      <geometry>
        <mesh filename="package://ballbot_arm_description/meshes/link_shoulder_2_uparm.stl"/>
      </geometry>
    </collision>
    <inertial>
      <origin rpy="0 0 0" xyz="0 0 0"/>
      <mass value="1.888"/>
      <inertia ixx="0.002866" ixy="0.0" ixz="0.0002159" iyy="0.005072" iyz="0.0" izz="0.004689"/>
    </inertial>
  </link>
  <joint name="l_JOINT3" type="continuous">
    <origin rpy="1.57079632679 0 0" xyz="0 0.150683 0"/>
    <axis xyz="0 0 1"/>
    <limit effort="5.0" lower="0" upper="6.28318530718" velocity="2.0"/>
    <parent link="l_shoulder_2_uparm_link"/>
    <child link="l_uparm_link"/>
    <dynamics damping="0.7"/>
  </joint>
  <link name="l_uparm_link">
    <visual>
      <origin rpy="0 0 -1.57079632679" xyz="0 0 0"/>
      <geometry>
        <mesh filename="package://ballbot_arm_description/meshes/link_uparm.stl"/>
      </geometry>
      <material name="blue"/>
    </visual>
    <collision>
      <origin rpy="0 0 -1.57079632679" xyz="0 0 0"/>
      <geometry>
        <mesh filename="package://ballbot_arm_description/meshes/link_uparm.stl"/>
      </geometry>
    </collision>
    <inertial>
      <origin rpy="0 0 0" xyz="0 0 0"/>
      <mass value="1.821"/>
      <inertia ixx="0.005026" ixy="0.0" ixz="0.0" iyy="0.005136" iyz="0.0004929" izz="0.002311"/>
    </inertial>
  </link>
  <joint name="l_JOINT4" type="revolute">
    <origin rpy="0 1.57079632679 0" xyz="0 0 -0.112431"/>
    <axis xyz="0 0 1"/>
    <limit effort="5.0" lower="-2.26892802759" upper="0.349065850399" velocity="2.0"/>
    <parent link="l_uparm_link"/>
    <child link="l_forearm_link"/>
    <dynamics damping="0.7"/>
  </joint>
  <link name="l_forearm_link">
    <visual>
      <origin rpy="3.14159265359 0 0" xyz="0 0 0"/>
      <geometry>
        <mesh filename="package://ballbot_arm_description/meshes/link_forearm.stl"/>
      </geometry>
      <material name="grey"/>
    </visual>
    <collision>
      <origin rpy="3.14159265359 0 0" xyz="0 0 0"/>
      <geometry>
        <mesh filename="package://ballbot_arm_description/meshes/link_forearm.stl"/>
      </geometry>
    </collision>
    <inertial>
      <origin rpy="0 0 0" xyz="0 0 0"/>
      <mass value="1.820"/>
      <inertia ixx="0.003260" ixy="0.0007391" ixz="-0.0001047" iyy="0.003214" iyz="-0.00005031" izz="0.003893"/>
    </inertial>
  </link>
  <joint name="l_JOINT5" type="continuous">
    <origin rpy="0 -1.57079632679 0" xyz="0.112 0.07 0"/>
    <axis xyz="0 0 1"/>
    <limit effort="5.0" lower="-6.28318530718" upper="6.28318530718" velocity="2.0"/>
    <parent link="l_forearm_link"/>
    <child link="l_forearm_2_wrist_link"/>
    <dynamics damping="0.7"/>
  </joint>
  <link name="l_forearm_2_wrist_link">
    <visual>
      <origin rpy="0 0 0" xyz="0 0 0"/>
      <geometry>
        <mesh filename="package://ballbot_arm_description/meshes/link_forearm_2_wrist.stl"/>
      </geometry>
      <material name="blue"/>
    </visual>
    <collision>
      <origin rpy="0 0 0" xyz="0 0 0"/>
      <geometry>
        <mesh filename="package://ballbot_arm_description/meshes/link_forearm_2_wrist.stl"/>
      </geometry>
    </collision>
    <inertial>
      <origin rpy="0 0 0" xyz="0 0 0"/>
      <mass value="0.973"/>
      <inertia ixx="0.001063" ixy="0" ixz="-0.00004093" iyy="0.001178" iyz="0" izz="0.0009625"/>
    </inertial>
  </link>
  <joint name="l_JOINT6" type="revolute">
    <origin rpy="0 -1.57079632679 0" xyz="0 0 -0.08"/>
    <axis xyz="0 0 1"/>
    <limit effort="5.0" lower="-1.57079632679" upper="1.57079632679" velocity="2.0"/>
    <parent link="l_forearm_2_wrist_link"/>
    <child link="l_wrist_mid_link"/>
    <dynamics damping="0.7"/>
  </joint>
  <link name="l_wrist_mid_link">
    <visual>
      <origin rpy="0 0 0" xyz="0 0 0"/>
      <geometry>
        <mesh filename="package://ballbot_arm_description/meshes/link_wrist_mid.stl"/>
      </geometry>
      <material name="grey"/>
    </visual>
    <collision>
      <origin rpy="0 0 0" xyz="0 0 0"/>
      <geometry>
        <mesh filename="package://ballbot_arm_description/meshes/link_wrist_mid.stl"/>
      </geometry>
    </collision>
    <inertial>
      <origin rpy="0 0 0" xyz="0 0 0"/>
      <mass value="1.013"/>
      <inertia ixx="0.0009954" ixy="0.0001979" ixz="0.00008468" iyy="0.002233" iyz="-0.00001389" izz="0.002236"/>
    </inertial>
  </link>
  <joint name="l_JOINT7" type="revolute">
    <origin rpy="-1.57079632679 0 0" xyz="-0.107616 -0.005 0"/>
    <axis xyz="0 0 1"/>
    <limit effort="5.0" lower="-1.57079632679" upper="1.57079632679" velocity="2.0"/>
    <parent link="l_wrist_mid_link"/>
    <child link="l_wrist_2_hand_link"/>
    <dynamics damping="0.7"/>
  </joint>
  <link name="l_wrist_2_hand_link">
    <visual>
      <origin rpy="0 0 0" xyz="0 0 0"/>
      <geometry>
        <mesh filename="package://ballbot_arm_description/meshes/link_wrist_2_hand.stl"/>
      </geometry>
      <material name="blue"/>
    </visual>
    <collision>
      <origin rpy="0 0 0" xyz="0 0 0"/>
      <geometry>
        <mesh filename="package://ballbot_arm_description/meshes/link_wrist_2_hand.stl"/>
      </geometry>
    </collision>
    <inertial>
      <origin rpy="0 0 0" xyz="0 0 0"/>
      <mass value="0.9524"/>
      <inertia ixx="0.0009135" ixy="0.0" ixz="0.00004441" iyy="0.001068" iyz="0.0" izz="0.0009050"/>
    </inertial>
  </link>
  <joint name="l_bh_base_joint" type="fixed">
    <origin rpy="0 -1.57079632679 0" xyz="-0.055 0 0"/>
    <parent link="l_wrist_2_hand_link"/>
    <child link="l_bh_base_link"/>
  </joint>
  <!-- HAND BASE_LINK (RED) -->
  <link name="l_bh_base_link">
    <inertial>
      <mass value="1.0"/>
      <origin xyz="0 0 0"/>
      <inertia ixx="1.0" ixy="0.0" ixz="0.0" iyy="1.0" iyz="0.0" izz="1.0"/>
    </inertial>
    <visual>
      <origin rpy="0 0 0" xyz="0 0 0"/>
      <geometry>
        <mesh filename="package://barrett_hand_description/meshes/palm_280.dae"/>
      </geometry>
      <material name="Grey">
        <color rgba="0.75 0.75 0.75 1.0"/>
      </material>
    </visual>
    <collision>
      <origin rpy="0 0 0 " xyz="0 0 0"/>
      <geometry>
        <mesh filename="package://barrett_hand_description/meshes/palm_280.dae"/>
      </geometry>
      <contact_coefficients kd="1.0" kp="1000.0" mu="0"/>
    </collision>
  </link>
  <!-- finger 3 -->
  <!-- finger 32 link -->
  <link name="l_bh_finger_32_link">
    <inertial>
      <mass value="0.1"/>
      <origin rpy="0 0 0" xyz="0 0 0"/>
      <inertia ixx="0.01" ixy="0" ixz="0" iyy="0.01" iyz="0" izz="0.01"/>
    </inertial>
    <visual>
      <origin rpy="0 0 0" xyz="0 0 0"/>
      <geometry>
        <mesh filename="package://barrett_hand_description/meshes/finger.dae"/>
      </geometry>
      <material name="Blue"/>
    </visual>
    <collision>
      <origin rpy="0 0 0" xyz="0 0 0"/>
      <geometry>
        <mesh filename="package://barrett_hand_description/meshes/finger.dae"/>
      </geometry>
      <contact_coefficients kd="1.0" kp="1000.0" mu="0"/>
    </collision>
  </link>
  <!-- joint between BH_finger_31_link and BH_finger_32_link -->
  <joint name="l_bh_j32_joint" type="revolute">
    <parent link="l_bh_base_link"/>
    <child link="l_bh_finger_32_link"/>
    <origin rpy="1.5708 1.5708 1.5708" xyz="0 -0.05 0.0754"/>
    <axis xyz="0 0 -1"/>
    <limit effort="30.0" lower="0.0" upper="2.44" velocity="2.0"/>
    <dynamics damping="100.0" friction="1.0"/>
  </joint>
  <transmission name="l_bh_j32_transmission">
    <type>transmission_interface/SimpleTransmission</type>
    <joint name="l_bh_j32_joint">
      <hardwareInterface>PositionJointInterface</hardwareInterface>
    </joint>
    <actuator name="l_bh_j32">
      <hardwareInterface>PositionJointInterface</hardwareInterface>
      <mechanicalReduction>1</mechanicalReduction>
      <motorTorqueConstant>1</motorTorqueConstant>
    </actuator>
  </transmission>
  <!-- finger 33 link -->
  <link name="l_bh_finger_33_link">
    <inertial>
      <mass value="0.1"/>
      <origin rpy="0 0 0" xyz="0 0 0"/>
      <inertia ixx="0.01" ixy="0" ixz="0" iyy="0.01" iyz="0" izz="0.01"/>
    </inertial>
    <visual>
      <origin rpy="0 0 0" xyz="0 0 0"/>
      <geometry>
        <mesh filename="package://barrett_hand_description/meshes/finger_tip.dae"/>
      </geometry>
      <material name="Blue"/>
    </visual>
    <collision>
      <origin rpy="0 0 0" xyz="0 0 0"/>
      <geometry>
        <mesh filename="package://barrett_hand_description/meshes/finger_tip.dae"/>
      </geometry>
      <contact_coefficients kd="1.0" kp="1000.0" mu="0"/>
    </collision>
  </link>
  <!-- joint between BH_finger_32_link and BH_finger_33_link -->
  <joint name="l_bh_j33_joint" type="revolute">
    <parent link="l_bh_finger_32_link"/>
    <child link="l_bh_finger_33_link"/>
    <origin rpy="0 0 0" xyz="-0.069936 0.003 0"/>
    <axis xyz="0 0 -1"/>
    <mimic joint="l_bh_j32_joint" multiplier="0.344262295082"/>
    <limit effort="30.0" lower="0.0" upper="0.84" velocity="2.0"/>
    <dynamics damping="100.0" friction="1.0"/>
  </joint>
  <transmission name="l_bh_j33_transmission">
    <type>transmission_interface/SimpleTransmission</type>
    <joint name="l_bh_j33_joint">
      <hardwareInterface>PositionJointInterface</hardwareInterface>
    </joint>
    <actuator name="l_bh_j33">
      <hardwareInterface>PositionJointInterface</hardwareInterface>
      <mechanicalReduction>1</mechanicalReduction>
      <motorTorqueConstant>1</motorTorqueConstant>
    </actuator>
  </transmission>
  <!-- finger 1 -->
  <!-- finger 11 link -->
  <link name="l_bh_finger_11_link">
    <inertial>
      <mass value="0.1"/>
      <origin rpy="0 0 0" xyz="-0.046 0 0"/>
      <inertia ixx="0.01" ixy="0" ixz="0" iyy="0.01" iyz="0" izz="0.01"/>
    </inertial>
    <visual>
      <origin rpy="0 0 0" xyz="0 0 0"/>
      <geometry>
        <mesh filename="package://barrett_hand_description/meshes/knuckle.dae"/>
      </geometry>
      <material name="Green"/>
    </visual>
    <collision>
      <origin rpy="0 0 0" xyz="0 0 0"/>
      <geometry>
        <mesh filename="package://barrett_hand_description/meshes/knuckle.dae"/>
      </geometry>
    </collision>
  </link>
  <!-- joint between BH_palm_link and BH_finger_11_link -->
  <joint name="l_bh_j11_joint" type="revolute">
    <parent link="l_bh_base_link"/>
    <child link="l_bh_finger_11_link"/>
    <origin rpy="0 0 -1.5708" xyz="0.025 0 0.0415"/>
    <axis xyz="0 0 -1"/>
    <limit effort="30.0" lower="0" upper="3.1416" velocity="2.0"/>
    <dynamics damping="100.0" friction="1.0"/>
  </joint>
  <transmission name="l_bh_j11_transmission">
    <type>transmission_interface/SimpleTransmission</type>
    <joint name="l_bh_j11_joint">
      <hardwareInterface>PositionJointInterface</hardwareInterface>
    </joint>
    <actuator name="l_bh_j11">
      <hardwareInterface>PositionJointInterface</hardwareInterface>
      <mechanicalReduction>1</mechanicalReduction>
      <motorTorqueConstant>1</motorTorqueConstant>
    </actuator>
  </transmission>
  <!-- finger 12 link -->
  <link name="l_bh_finger_12_link">
    <inertial>
      <mass value="0.1"/>
      <origin rpy="0 0 0" xyz="0 0 0"/>
      <inertia ixx="0.01" ixy="0" ixz="0" iyy="0.01" iyz="0" izz="0.01"/>
    </inertial>
    <visual>
      <origin rpy="0 0 0" xyz="0 0 0"/>
      <geometry>
        <mesh filename="package://barrett_hand_description/meshes/finger.dae"/>
      </geometry>
      <material name="Blue"/>
    </visual>
    <collision>
      <origin rpy="0 0 0" xyz="0 0 0"/>
      <geometry>
        <mesh filename="package://barrett_hand_description/meshes/finger.dae"/>
      </geometry>
      <contact_coefficients kd="1.0" kp="1000.0" mu="0"/>
    </collision>
  </link>
  <!-- joint between BH_finger_11_link and BH_finger_12_link -->
  <joint name="l_bh_j12_joint" type="revolute">
    <parent link="l_bh_finger_11_link"/>
    <child link="l_bh_finger_12_link"/>
    <origin rpy="1.5708 1.5708 0" xyz="-0.05 0 0.0339"/>
    <axis xyz="0 0 -1"/>
    <limit effort="30.0" lower="0.0" upper="2.44" velocity="2.0"/>
    <dynamics damping="100.0" friction="1.0"/>
  </joint>
  <transmission name="l_bh_j12_transmission">
    <type>transmission_interface/SimpleTransmission</type>
    <joint name="l_bh_j12_joint">
      <hardwareInterface>PositionJointInterface</hardwareInterface>
    </joint>
    <actuator name="l_bh_j12">
      <hardwareInterface>PositionJointInterface</hardwareInterface>
      <mechanicalReduction>1</mechanicalReduction>
      <motorTorqueConstant>1</motorTorqueConstant>
    </actuator>
  </transmission>
  <!-- finger 13 link -->
  <link name="l_bh_finger_13_link">
    <inertial>
      <mass value="0.1"/>
      <origin rpy="0 0 0" xyz="0 0 0"/>
      <inertia ixx="0.01" ixy="0" ixz="0" iyy="0.01" iyz="0" izz="0.01"/>
    </inertial>
    <visual>
      <origin rpy="0 0 0" xyz="0 0 0"/>
      <geometry>
        <mesh filename="package://barrett_hand_description/meshes/finger_tip.dae"/>
      </geometry>
      <material name="Blue"/>
    </visual>
    <collision>
      <origin rpy="0 0 0" xyz="0 0 0"/>
      <geometry>
        <mesh filename="package://barrett_hand_description/meshes/finger_tip.dae"/>
      </geometry>
      <contact_coefficients kd="1.0" kp="1000.0" mu="0"/>
    </collision>
  </link>
  <!-- joint between BH_finger_12_link and BH_finger_13_link -->
  <joint name="l_bh_j13_joint" type="revolute">
    <parent link="l_bh_finger_12_link"/>
    <child link="l_bh_finger_13_link"/>
    <origin rpy="0 0 0" xyz="-0.069936 0.003 0"/>
    <axis xyz="0 0 -1"/>
    <mimic joint="l_bh_j12_joint" multiplier="0.344262295082"/>
    <limit effort="30.0" lower="0.0" upper="0.84" velocity="2.0"/>
    <dynamics damping="100.0" friction="1.0"/>
  </joint>
  <transmission name="l_bh_j13_transmission">
    <type>transmission_interface/SimpleTransmission</type>
    <joint name="l_bh_j13_joint">
      <hardwareInterface>PositionJointInterface</hardwareInterface>
    </joint>
    <actuator name="l_bh_j13">
      <hardwareInterface>PositionJointInterface</hardwareInterface>
      <mechanicalReduction>1</mechanicalReduction>
      <motorTorqueConstant>1</motorTorqueConstant>
    </actuator>
  </transmission>
  <!-- finger 2 -->
  <!-- finger 21 link -->
  <link name="l_bh_finger_21_link">
    <inertial>
      <mass value="0.1"/>
      <origin rpy="0 0 0" xyz="-0.046 0 0"/>
      <inertia ixx="0.01" ixy="0" ixz="0" iyy="0.01" iyz="0" izz="0.01"/>
    </inertial>
    <visual>
      <origin rpy="0 0 0" xyz="0 0 0"/>
      <geometry>
        <mesh filename="package://barrett_hand_description/meshes/knuckle.dae"/>
      </geometry>
      <material name="Green"/>
    </visual>
    <collision>
      <origin rpy="0 0 0" xyz="0 0 0"/>
      <geometry>
        <mesh filename="package://barrett_hand_description/meshes/knuckle.dae"/>
      </geometry>
    </collision>
  </link>
  <!-- joint between BH_palm_link and BH_finger_21_link -->
  <joint name="l_bh_j21_joint" type="revolute">
    <parent link="l_bh_base_link"/>
    <child link="l_bh_finger_21_link"/>
    <origin rpy="0 0 -1.5708" xyz="-0.025 0 0.0415"/>
    <axis xyz="0 0 1"/>
    <mimic joint="l_bh_j11_joint" multiplier="1"/>
    <limit effort="30.0" lower="0" upper="3.1416" velocity="2.0"/>
    <dynamics damping="100.0" friction="1.0"/>
  </joint>
  <transmission name="l_bh_j21_transmission">
    <type>transmission_interface/SimpleTransmission</type>
    <joint name="l_bh_j21_joint">
      <hardwareInterface>PositionJointInterface</hardwareInterface>
    </joint>
    <actuator name="l_bh_j21">
      <hardwareInterface>PositionJointInterface</hardwareInterface>
      <mechanicalReduction>1</mechanicalReduction>
      <motorTorqueConstant>1</motorTorqueConstant>
    </actuator>
  </transmission>
  <!-- finger 12 link -->
  <link name="l_bh_finger_22_link">
    <inertial>
      <mass value="0.1"/>
      <origin rpy="0 0 0" xyz="0 0 0"/>
      <inertia ixx="0.01" ixy="0" ixz="0" iyy="0.01" iyz="0" izz="0.01"/>
    </inertial>
    <visual>
      <origin rpy="0 0 0" xyz="0 0 0"/>
      <geometry>
        <mesh filename="package://barrett_hand_description/meshes/finger.dae"/>
      </geometry>
      <material name="Blue"/>
    </visual>
    <collision>
      <origin rpy="0 0 0" xyz="0 0 0"/>
      <geometry>
        <mesh filename="package://barrett_hand_description/meshes/finger.dae"/>
      </geometry>
      <contact_coefficients kd="1.0" kp="1000.0" mu="0"/>
    </collision>
  </link>
  <!-- joint between BH_finger_21_link and BH_finger_22_link -->
  <joint name="l_bh_j22_joint" type="revolute">
    <parent link="l_bh_finger_21_link"/>
    <child link="l_bh_finger_22_link"/>
    <origin rpy="1.5708 1.5708 0" xyz="-0.05 0 0.0339"/>
    <axis xyz="0 0 -1"/>
    <limit effort="30.0" lower="0.0" upper="2.44" velocity="2.0"/>
    <dynamics damping="100.0" friction="1.0"/>
  </joint>
  <transmission name="l_bh_j22_transmission">
    <type>transmission_interface/SimpleTransmission</type>
    <joint name="l_bh_j22_joint">
      <hardwareInterface>PositionJointInterface</hardwareInterface>
    </joint>
    <actuator name="l_bh_j22">
      <hardwareInterface>PositionJointInterface</hardwareInterface>
      <mechanicalReduction>1</mechanicalReduction>
      <motorTorqueConstant>1</motorTorqueConstant>
    </actuator>
  </transmission>
  <!-- finger 23 link -->
  <link name="l_bh_finger_23_link">
    <inertial>
      <mass value="0.1"/>
      <origin rpy="0 0 0" xyz="0 0 0"/>
      <inertia ixx="0.01" ixy="0" ixz="0" iyy="0.01" iyz="0" izz="0.01"/>
    </inertial>
    <visual>
      <origin rpy="0 0 0" xyz="0 0 0"/>
      <geometry>
        <mesh filename="package://barrett_hand_description/meshes/finger_tip.dae"/>
      </geometry>
      <material name="Blue"/>
    </visual>
    <collision>
      <origin rpy="0 0 0" xyz="0 0 0"/>
      <geometry>
        <mesh filename="package://barrett_hand_description/meshes/finger_tip.dae"/>
      </geometry>
      <contact_coefficients kd="1.0" kp="1000.0" mu="0"/>
    </collision>
  </link>
  <!-- joint between BH_finger_22_link and BH_finger_23_link -->
  <joint name="l_bh_j23_joint" type="revolute">
    <parent link="l_bh_finger_22_link"/>
    <child link="l_bh_finger_23_link"/>
    <origin rpy="0 0 0" xyz="-0.069936 0.003 0"/>
    <axis xyz="0 0 -1"/>
    <mimic joint="l_bh_j22_joint" multiplier="0.344262295082"/>
    <limit effort="30.0" lower="0.0" upper="0.84" velocity="2.0"/>
    <dynamics damping="100.0" friction="1.0"/>
  </joint>
  <transmission name="l_bh_j23_transmission">
    <type>transmission_interface/SimpleTransmission</type>
    <joint name="l_bh_j23_joint">
      <hardwareInterface>PositionJointInterface</hardwareInterface>
    </joint>
    <actuator name="l_bh_j23">
      <hardwareInterface>PositionJointInterface</hardwareInterface>
      <mechanicalReduction>1</mechanicalReduction>
      <motorTorqueConstant>1</motorTorqueConstant>
    </actuator>
  </transmission>
  <gazebo>
    <plugin filename="libgazebo_mimic_plugin.so" name="mimic_plugin">
      <joint>l_bh_j11_joint</joint>
      <mimicJoint>l_bh_j21_joint</mimicJoint>
      <multiplier>1</multiplier>
    </plugin>
  </gazebo>
  <gazebo>
    <plugin filename="libgazebo_mimic_plugin.so" name="mimic_plugin">
      <joint>l_bh_j12_joint</joint>
      <mimicJoint>l_bh_j13_joint</mimicJoint>
      <multiplier>0.344</multiplier>
    </plugin>
  </gazebo>
  <gazebo>
    <plugin filename="libgazebo_mimic_plugin.so" name="mimic_plugin">
      <joint>l_bh_j22_joint</joint>
      <mimicJoint>l_bh_j23_joint</mimicJoint>
      <multiplier>0.344</multiplier>
    </plugin>
  </gazebo>
  <gazebo>
    <plugin filename="libgazebo_mimic_plugin.so" name="mimic_plugin">
      <joint>l_bh_j32_joint</joint>
      <mimicJoint>l_bh_j33_joint</mimicJoint>
      <multiplier>0.344</multiplier>
    </plugin>
  </gazebo>
  <gazebo reference="l_bh_base_link">
    <material>Gazebo/White</material>
    <turnGravityOff>False</turnGravityOff>
  </gazebo>
  <gazebo reference="l_bh_finger_31_link">
    <material>Gazebo/Grey</material>
    <turnGravityOff>False</turnGravityOff>
  </gazebo>
  <gazebo reference="l_bh_finger_32_link">
    <material>Gazebo/Grey</material>
    <turnGravityOff>False</turnGravityOff>
  </gazebo>
  <gazebo reference="l_bh_finger_33_link">
    <material>Gazebo/Grey</material>
    <turnGravityOff>False</turnGravityOff>
  </gazebo>
  <gazebo reference="l_bh_finger_11_link">
    <material>Gazebo/Grey</material>
    <turnGravityOff>False</turnGravityOff>
  </gazebo>
  <gazebo reference="l_bh_finger_12_link">
    <material>Gazebo/Grey</material>
    <turnGravityOff>False</turnGravityOff>
  </gazebo>
  <gazebo reference="l_bh_finger_13_link">
    <material>Gazebo/Grey</material>
    <turnGravityOff>False</turnGravityOff>
  </gazebo>
  <gazebo reference="l_bh_finger_21_link">
    <material>Gazebo/Grey</material>
    <turnGravityOff>False</turnGravityOff>
  </gazebo>
  <gazebo reference="l_bh_finger_22_link">
    <material>Gazebo/Grey</material>
    <turnGravityOff>False</turnGravityOff>
  </gazebo>
  <gazebo reference="l_bh_finger_23_link">
    <material>Gazebo/Grey</material>
    <turnGravityOff>False</turnGravityOff>
  </gazebo>
  <!-- Imaginary joints for transform from tactile sensors -->
  <!-- Radian value obtained from graspit description of 40 degrees -->
  <!-- <joint name="${name}_finger_14_joint" type="fixed">
			<parent link="${name}_finger_13_link"/>
			<child link="${name}_finger_14_link"/>
			<origin xyz="0 0 0" rpy="0 0 0.698132" />
		</joint>
		<link name="${name}_finger_14_link"/>

		<joint name="${name}_finger_24_joint" type="fixed">
			<parent link="${name}_finger_23_link"/>
			<child link="${name}_finger_24_link"/>
			<origin xyz="0 0 0" rpy="0 0 0.698132" />
		</joint>
		<link name="${name}_finger_24_link"/>

		<joint name="${name}_finger_34_joint" type="fixed">
			<parent link="${name}_finger_33_link"/>
			<child link="${name}_finger_34_link"/>
			<origin xyz="0 0 0" rpy="0 0 0.698132" />
		</joint>
		<link name="${name}_finger_34_link"/> -->
  <!-- Auto generated tactile sensor links -->
  <!-- <xacro:bh_tactile name="bh"/> -->
</robot>
