<?xml version="1.0" encoding="utf-8"?>
<!-- =================================================================================== -->
<!-- |    This document was autogenerated by xacro from ballbot_plus_fixedbase.urdf.xacro | -->
<!-- |    EDITING THIS FILE BY HAND IS NOT RECOMMENDED                                 | -->
<!-- =================================================================================== -->
<!-- Overview: Ballbot Plus (ballbot + 2x7DOF arms) reprsented as a floating base system -->
<robot name="ballbot">
  <!-- CAD -->
  <material name="black">
    <color rgba="0.0 0.0 0.0 1.0"/>
  </material>

  <material name="cian">
    <color rgba="0.0 0.8 0.8 1.0"/>
  </material>

  <material name="blue">
    <color rgba="0.0 0.0 0.8 1.0"/>
  </material>
  <material name="green">
    <color rgba="0.0 0.8 0.0 1.0"/>
  </material>
  <material name="dark_grey">
    <color rgba="0.2 0.2 0.2 1.0"/>
  </material>
  <material name="grey">
    <color rgba="0.5 0.5 0.5 1.0"/>
  </material>
  <material name="light_grey">
    <color rgba="0.8 0.8 0.8 1.0"/>
  </material>
  <material name="orange">
    <color rgba="1.0 0.423529411765 0.0392156862745 1.0"/>
  </material>
  <material name="brown">
    <color rgba="0.870588235294 0.811764705882 0.764705882353 1.0"/>
  </material>
  <material name="white">
    <color rgba="1.0 1.0 1.0 1.0"/>
  </material>
  <material name="yellow">
    <color rgba="0.8 0.68 0.0 1.0"/>
  </material>
  <material name="red">
    <color rgba="1.0 0.0 0.0 1"/>
  </material>
  <material name="aluminum">
    <color rgba="0.5 0.5 0.5 1"/>
  </material>
  <!-- Use of macros to assemble the robot -->
  <!-- ====================================== -->
  <!-- Used for fixing robot to Gazebo 'base_link' -->
  <link name="base_link"/>
  <link name="Link_Xtran">
    <inertial>
      <origin xyz="0.00000 0.00000 0.00000"/>
      <mass value="0.00001"/>
      <inertia ixx="0.0000001" ixy="0.0" ixz="0.0" iyy="0.0000001" iyz="0.0" izz="0.0000001"/>
    </inertial>
  </link>
  <link name="Link_Ytran">
    <inertial>
      <origin xyz="0.00000 0.00000 0.00000"/>
      <mass value="0.00001"/>
      <inertia ixx="0.0000001" ixy="0.0" ixz="0.0" iyy="0.0000001" iyz="0.0" izz="0.0000001"/>
    </inertial>
  </link>
  <link name="Link_Ball">
    <visual>
      <origin rpy="0.0 0.0 0.0" xyz="0.0 0.0 0.0"/>
      <geometry>
        <mesh filename="package://ballbot_arm_description/meshes/v2020/ball.stl"/>
      </geometry>
      <material name="orange"/>
    </visual>
    <collision>
      <origin rpy="0 0 0" xyz="0 0 0"/>
      <geometry>
        <mesh filename="package://ballbot_arm_description/meshes/v2020/ball.stl"/>
      </geometry>
    </collision>
    <inertial>
      <origin xyz="0.0 0.0 0.0"/>
      <mass value="2.72"/>
      <inertia ixx="0.01220" ixy="0.00000" ixz="0.00000" iyy="0.01220" iyz="0.00000" izz="0.01220"/>
    </inertial>
  </link>
  <link name="Link_Pitch">
    <inertial>
      <origin xyz="0.00000 0.00000 0.00000"/>
      <mass value="0.00001"/>
      <inertia ixx="0.0000001" ixy="0.0" ixz="0.0" iyy="0.0000001" iyz="0.0" izz="0.0000001"/>
    </inertial>
  </link>
  <link name="Link_Roll">
    <inertial>
      <origin xyz="0.00000 0.00000 0.00000"/>
      <mass value="0.00001"/>
      <inertia ixx="0.0000001" ixy="0.0" ixz="0.0" iyy="0.0000001" iyz="0.0" izz="0.0000001"/>
    </inertial>
  </link>
  <link name="Link_Yaw">
    <inertial>
      <origin xyz="0.00000 0.00000 0.00000"/>
      <mass value="0.00001"/>
      <inertia ixx="0.0000001" ixy="0.0" ixz="0.0" iyy="0.0000001" iyz="0.0" izz="0.0000001"/>
    </inertial>
  </link>
  <!-- Joints -->
  <joint name="Joint_World_Xtran" type="prismatic">
    <origin rpy="0.0 0.0 0.0" xyz="0.0 0. 0.0"/>
    <parent link="base_link"/>
    <child link="Link_Xtran"/>
    <limit effort="30" lower="-10" upper="10" velocity="1.0"/>
    <axis xyz="0 -1 0"/>
  </joint>
  <joint name="Joint_World_Ytran" type="prismatic">
    <origin rpy="0.0 0.0 0.0" xyz="0.0 0.0 0.0"/>
    <parent link="Link_Xtran"/>
    <child link="Link_Ytran"/>
    <limit effort="30" lower="-10" upper="10" velocity="1.0"/>
    <axis xyz="1 0 0"/>
  </joint>
  <joint name="Joint_World_Ball" type="fixed">
    <origin rpy="0.0 0.0 0.0" xyz="0.0 0.0 0.105838"/>
    <parent link="Link_Ytran"/>
    <child link="Link_Ball"/>
    <axis xyz="0 0 1"/>
  </joint>
  <joint name="xAngle" type="revolute">
    <origin rpy="0.0 0.0 0.0" xyz="0.0 0.0 0.0"/>
    <parent link="Link_Ball"/>
    <child link="Link_Pitch"/>
    <limit effort="30" lower="-0.349065850399" upper="0.349065850399" velocity="1.0"/>
    <axis xyz="1 0 0"/>
  </joint>
  <joint name="yAngle" type="revolute">
    <origin rpy="0.0 0.0 0.0" xyz="0.00000 0.00000 0.00000"/>
    <parent link="Link_Pitch"/>
    <child link="Link_Roll"/>
    <limit effort="30" lower="-0.349065850399" upper="0.349065850399" velocity="1.0"/>
    <axis xyz="0 1 0"/>
  </joint>
  <joint name="yaw" type="revolute">
    <origin rpy="0.0 0.0 0.0" xyz="0.00000 0.00000 0.0"/>
    <parent link="Link_Roll"/>
    <child link="Link_Yaw"/>
    <limit effort="30" lower="-3.14159265359" upper="3.14159265359" velocity="1.0"/>
    <axis xyz="0 0 1"/>
  </joint>
  <joint name="JBalltoBody" type="fixed">
    <origin rpy="0.0 0.0 1.5707963268" xyz="0.0 0.0 0.762"/>
    <parent link="Link_Yaw"/>
    <child link="Link_Body"/>
    <limit effort="30" velocity="1.0"/>
    <axis xyz="0 0 1"/>
  </joint>
  <link name="Link_Body">
    <inertial>
      <origin xyz="0.015 0.0005 -0.015"/>
      <mass value="64.86"/>
      <inertia ixx="10.61648" ixy="0.00000" ixz="0.00000" iyy="10.61648" iyz="0.00000" izz="0.66440"/>
    </inertial>
    <visual>
      <origin rpy="0 0 0" xyz="0 0 -0.762"/>
      <geometry>
        <mesh filename="package://ballbot_arm_description/meshes/v2020/ballbot_body_v2021.stl"/>
      </geometry>
      <material name="yellow"/>
    </visual>
    <collision>
      <origin rpy="0 0 0" xyz="0 0 -0.0595"/>
      <geometry>
        <cylinder length="1.105" radius="0.184"/>
      </geometry>
    </collision>
  </link>
  <joint name="turret_pan" type="fixed">
    <origin rpy="0 0 0" xyz="0 0 0.656162"/>
    <parent link="Link_Body"/>
    <child link="turret_plate_link"/>
    <limit effort="1000." lower="-6.1" upper="6.1" velocity="1.0"/>
    <axis xyz="0 0 1"/>
    <dynamics damping="1.0" friction="1.0"/>
  </joint>
  <link name="turret_plate_link">
    <visual>
      <origin rpy="0 0 0" xyz="0.0 0.0 0.0"/>
      <geometry>
        <mesh filename="package://ballbot_arm_description/meshes/v2020/turret_pan.stl"/>
      </geometry>
      <material name="grey"/>
    </visual>
    <inertial>
      <origin xyz="0.0 0.0 0.0"/>
      <mass value="0.0"/>
      <inertia ixx="0.0" ixy="0.00000" ixz="0.00000" iyy="0.0" iyz="0.00000" izz="0.0"/>
    </inertial>
  </link>
  <joint name="turret_tilt" type="fixed">
    <origin rpy="1.5707963268 0 3.14159265359" xyz="0.15557 -0.0347980 0.0541020"/>
    <parent link="turret_plate_link"/>
    <child link="turret_tilt_link"/>
    <limit effort="1000.0" lower="-0.05" upper="1.5707963268" velocity="1.0"/>
    <axis xyz="0 0 1"/>
    <dynamics damping="1.0" friction="1.0"/>
  </joint>
  <link name="turret_tilt_link">
    <visual>
      <origin rpy="0 0 0" xyz="0.0 0.0 0.0"/>
      <geometry>
        <mesh filename="package://ballbot_arm_description/meshes/v2020/turret_tilt.stl"/>
      </geometry>
      <material name="brown"/>
    </visual>
    <inertial>
      <origin xyz="0.0 0.0 0.0"/>
      <mass value="0.0"/>
      <inertia ixx="0.0" ixy="0.00000" ixz="0.00000" iyy="0.0" iyz="0.00000" izz="0.0"/>
    </inertial>
  </link>
  <!-- ====================================== -->
</robot>
