<?xml version="1.0" ?>
<!-- =================================================================================== -->
<!-- |    This document was autogenerated by xacro from robots/ballbot_plus.urdf.xacro | -->
<!-- |    EDITING THIS FILE BY HAND IS NOT RECOMMENDED                                 | -->
<!-- =================================================================================== -->
<robot name="ballbot" xmlns:xacro="http://ros.org/wiki/xacro">
  <material name="black">
    <color rgba="0.0 0.0 0.0 1.0"/>
  </material>
  <material name="blue">
    <color rgba="0.0 0.0 0.8 1.0"/>
  </material>
  <material name="green">
    <color rgba="0.0 0.8 0.0 1.0"/>
  </material>
  <material name="grey">
    <color rgba="0.5 0.5 0.5 1.0"/>
  </material>
  <material name="orange">
    <color rgba="1.0 0.423529411765 0.0392156862745 1.0"/>
  </material>
  <material name="brown">
    <color rgba="0.870588235294 0.811764705882 0.764705882353 1.0"/>
  </material>
  <material name="white">
    <color rgba="1.0 1.0 1.0 1.0"/>
  </material>
  <material name="yellow">
    <color rgba="0.8 0.68 0 1"/>
  </material>
  <material name="red">
    <color rgba="1.0 0.0 0.0 1"/>
  </material>
  <material name="aluminum">
    <color rgba="0.5 0.5 0.5 1"/>
  </material>
  <!-- Use of macros to assemble the robot -->
  <link name="BallbotBase">
    </link>
  <link name="Link_FakeBall">
    <inertial>
      <origin xyz="0.00000 0.00000 0.00000"/>
      <mass value="0.00000"/>
      <inertia ixx="0.00000" ixy="-0.00000" ixz="-0.00000" iyy="0.00000" iyz="-0.00000" izz="0.00000"/>
    </inertial>
  </link>
  <link name="Link_Ball">
    <inertial>
      <origin xyz="0.00000 0.00000 0.00000"/>
      <mass value="2.72"/>
      <inertia ixx="0.01220" ixy="-0.00000" ixz="-0.00000" iyy="0.01220" iyz="-0.00000" izz="0.01220"/>
    </inertial>
    <visual>
      <origin rpy="0.0 0.0 0.0" xyz="0.0 0.0 0.0"/>
      <geometry>
        <sphere radius="0.105838"/>
      </geometry>
      <material name="orange"/>
    </visual>
  </link>
  <link name="Link_FakeBody">
    <inertial>
      <origin xyz="0.00000 0.00000 0.00000"/>
      <mass value="0.00000"/>
      <inertia ixx="0.00000" ixy="-0.00000" ixz="-0.00000" iyy="0.00000" iyz="-0.00000" izz="0.00000"/>
    </inertial>
  </link>
  <link name="Link_Body">
    <inertial>
      <origin xyz="-0.762 0.00000 0.00000"/>
      <mass value="64.86"/>
      <inertia ixx="0.66440" ixy="-0.00000" ixz="-0.00000" iyy="10.61648" iyz="-0.00000" izz="10.61648"/>
    </inertial>
    <visual>
      <!--<origin xyz="${-BODY_HEIGHT/2} 0.0 0.0" rpy="0.0 -1.57079632679 0.0"/>-->
      <origin rpy="0 -1.57079632679 0" xyz="0 0 0"/>
      <geometry>
        <!--<cylinder length="${BODY_HEIGHT}" radius="${BODY_RADIUS}"/>-->
        <mesh filename="package://ballbot_arm_description/meshes/v2020/ballbot_body_v2020.stl"/>
      </geometry>
      <material name="yellow"/>
    </visual>
    <collision>
      <origin rpy="0 -1.57079632679 0" xyz="0 0 0.7025"/>
      <geometry>
        <cylinder length="1.405" radius="0.184"/>
      </geometry>
    </collision>
  </link>
  <link name="LArm0">
    <inertial>
      <origin rpy="0 0 0" xyz="0.0 0.0 0.0"/>
      <mass value="2.367"/>
      <inertia ixx="0.003661" ixy="0.0" ixz="0.00002075" iyy="0.003977" iyz="0.0" izz="0.004605"/>
    </inertial>
    <visual>
      <origin rpy="0 0 0" xyz="0 0 0"/>
      <geometry>
        <mesh filename="package://ballbot_arm_description/meshes/link_base.stl"/>
      </geometry>
      <material name="grey"/>
    </visual>
    <collision>
      <origin rpy="0 0 0" xyz="0 0 0"/>
      <geometry>
        <mesh filename="package://ballbot_arm_description/meshes/link_base.stl"/>
      </geometry>
    </collision>
  </link>
  <link name="LArm1">
    <inertial>
      <origin xyz="0.00063 0.00002 -0.04334"/>
      <mass value="1.52300"/>
      <inertia ixx="-2.48036" ixy="0.00080" ixz="-0.07684" iyy="-2.50246" iyz="0.00260" izz="1.30080"/>
    </inertial>
    <visual>
      <origin rpy="0 0 0" xyz="0.0 0.0 0.0"/>
      <geometry>
        <mesh filename="package://ballbot_arm_description/meshes/v2020/link_shoulder_2_base.stl"/>
      </geometry>
      <material name="brown"/>
    </visual>
    <collision>
      <origin rpy="0 0 0" xyz="0.0 0.0 -0.05525"/>
      <geometry>
        <cylinder length="0.1105" radius="0.05"/>
      </geometry>
      <material name="blue"/>
    </collision>
  </link>
  <link name="LArm2">
    <inertial>
      <origin xyz="0.00063 0.00002 -0.04334"/>
      <mass value="1.52300"/>
      <inertia ixx="-2.48036" ixy="0.00080" ixz="-0.07684" iyy="-2.50246" iyz="0.00260" izz="1.30080"/>
    </inertial>
    <visual>
      <origin rpy="0 0 0" xyz="0.0 0.0 0.0"/>
      <geometry>
        <mesh filename="package://ballbot_arm_description/meshes/v2020/link_shoulder_2_uparm.stl"/>
      </geometry>
      <material name="grey"/>
    </visual>
    <collision>
      <origin rpy="0 0 0" xyz="0.0 0.0 -0.05525"/>
      <geometry>
        <cylinder length="0.1105" radius="0.05"/>
      </geometry>
      <material name="blue"/>
    </collision>
  </link>
  <link name="LArm3">
    <inertial>
      <origin xyz="0.00069 0.00003 -0.03966"/>
      <mass value="1.47100"/>
      <inertia ixx="1.84769" ixy="-0.00110" ixz="-0.07294" iyy="1.87169" iyz="0.00460" izz="1.28440"/>
    </inertial>
    <visual>
      <origin rpy="0 0 0" xyz="0.0 0.0 -0.02718"/>
      <geometry>
        <mesh filename="package://ballbot_arm_description/meshes/v2020/link_upperarm.stl"/>
      </geometry>
      <material name="brown"/>
    </visual>
    <collision>
      <origin rpy="0 0 0" xyz="0.0 0.0 -0.05525"/>
      <geometry>
        <cylinder length="0.1105" radius="0.05"/>
      </geometry>
      <material name="blue"/>
    </collision>
  </link>
  <link name="LArm4">
    <inertial>
      <origin xyz="0.00069 0.00003 -0.03966"/>
      <mass value="1.47100"/>
      <inertia ixx="1.84769" ixy="-0.00110" ixz="-0.07294" iyy="1.87169" iyz="0.00460" izz="1.28440"/>
    </inertial>
    <visual>
      <!--<origin xyz="0.0 0.0 -0.05525" rpy="0 0 0"/>-->
      <origin rpy="0 0 0" xyz="0.0 0.0 0.0"/>
      <geometry>
        <!--<cylinder length="0.1105" radius="0.05"/>-->
        <mesh filename="package://ballbot_arm_description/meshes/v2020/link_forearm.stl"/>
      </geometry>
      <material name="grey"/>
    </visual>
    <collision>
      <origin rpy="0 0 0" xyz="0.0 0.0 -0.05525"/>
      <geometry>
        <cylinder length="0.1105" radius="0.05"/>
      </geometry>
      <material name="blue"/>
    </collision>
  </link>
  <link name="LArm5">
    <inertial>
      <origin xyz="0.00055 -0.00009 -0.03811"/>
      <mass value="0.75700"/>
      <inertia ixx="1.37630" ixy="-0.00120" ixz="-0.04232" iyy="1.38480" iyz="-0.00140" izz="0.50580"/>
    </inertial>
    <visual>
      <origin rpy="0 0 0" xyz="0.0 0.0 0.0"/>
      <geometry>
        <mesh filename="package://ballbot_arm_description/meshes/v2020/link_forearm_2_wrist.stl"/>
      </geometry>
      <material name="brown"/>
    </visual>
    <collision>
      <origin rpy="0 0 0" xyz="0.0 0.0 -0.05525"/>
      <geometry>
        <cylinder length="0.1105" radius="0.05"/>
      </geometry>
      <material name="blue"/>
    </collision>
  </link>
  <link name="LArm6">
    <inertial>
      <origin xyz="0.00055 -0.00009 -0.03811"/>
      <mass value="0.75700"/>
      <inertia ixx="1.37630" ixy="-0.00120" ixz="-0.04232" iyy="1.38480" iyz="-0.00140" izz="0.50580"/>
    </inertial>
    <visual>
      <origin rpy="0 0 0" xyz="0.0 0.0 0.0"/>
      <geometry>
        <mesh filename="package://ballbot_arm_description/meshes/v2020/link_wrist_mid.stl"/>
      </geometry>
      <material name="grey"/>
    </visual>
    <collision>
      <origin rpy="0 0 0" xyz="0.0 0.0 -0.05525"/>
      <geometry>
        <cylinder length="0.1105" radius="0.05"/>
      </geometry>
      <material name="blue"/>
    </collision>
  </link>
  <link name="LArm7">
    <inertial>
      <origin xyz="0.00055 -0.00009 -0.03811"/>
      <mass value="0.75700"/>
      <inertia ixx="1.37630" ixy="-0.00120" ixz="-0.04232" iyy="1.38480" iyz="-0.00140" izz="0.50580"/>
    </inertial>
    <visual>
      <origin rpy="0 0 0" xyz="0.0 0.0 0.0"/>
      <geometry>
        <mesh filename="package://ballbot_arm_description/meshes/v2020/link_wrist_2_hand.stl"/>
      </geometry>
      <material name="brown"/>
    </visual>
    <collision>
      <origin rpy="0 0 0" xyz="0.0 0.0 -0.05525"/>
      <geometry>
        <cylinder length="0.1105" radius="0.05"/>
      </geometry>
      <material name="blue"/>
    </collision>
  </link>
  <link name="RArm0">
    <inertial>
      <origin rpy="0 0 0" xyz="0.0 0.0 0.0"/>
      <mass value="2.367"/>
      <inertia ixx="0.003661" ixy="0.0" ixz="0.00002075" iyy="0.003977" iyz="0.0" izz="0.004605"/>
    </inertial>
    <visual>
      <origin rpy="0 0 0" xyz="0 0 0"/>
      <geometry>
        <mesh filename="package://ballbot_arm_description/meshes/link_base.stl"/>
      </geometry>
      <material name="grey"/>
    </visual>
    <collision>
      <origin rpy="0 0 0" xyz="0 0 0"/>
      <geometry>
        <mesh filename="package://ballbot_arm_description/meshes/link_base.stl"/>
      </geometry>
    </collision>
  </link>
  <link name="RArm1">
    <inertial>
      <origin xyz="0.00063 0.00002 -0.04334"/>
      <mass value="1.52300"/>
      <inertia ixx="-2.48036" ixy="0.00080" ixz="-0.07684" iyy="-2.50246" iyz="0.00260" izz="1.30080"/>
    </inertial>
    <visual>
      <origin rpy="0 0 3.14159265359" xyz="0.0 0.0 0.0"/>
      <geometry>
        <mesh filename="package://ballbot_arm_description/meshes/v2020/link_shoulder_2_base.stl"/>
      </geometry>
      <material name="brown"/>
    </visual>
    <collision>
      <origin rpy="0 0 0" xyz="0.0 0.0 -0.05525"/>
      <geometry>
        <cylinder length="0.1105" radius="0.05"/>
      </geometry>
    </collision>
  </link>
  <link name="RArm2">
    <inertial>
      <origin xyz="0.00063 0.00002 -0.04334"/>
      <mass value="1.52300"/>
      <inertia ixx="-2.48036" ixy="0.00080" ixz="-0.07684" iyy="-2.50246" iyz="0.00260" izz="1.30080"/>
    </inertial>
    <visual>
      <origin rpy="0 0 0" xyz="0.0 0.0 0.0"/>
      <geometry>
        <mesh filename="package://ballbot_arm_description/meshes/v2020/link_shoulder_2_uparm.stl"/>
      </geometry>
      <material name="grey"/>
    </visual>
    <collision>
      <origin rpy="0 0 0" xyz="0.0 0.0 -0.05525"/>
      <geometry>
        <cylinder length="0.1105" radius="0.05"/>
      </geometry>
    </collision>
  </link>
  <link name="RArm3">
    <inertial>
      <origin xyz="0.00069 0.00003 -0.03966"/>
      <mass value="1.47100"/>
      <inertia ixx="1.84769" ixy="-0.00110" ixz="-0.07294" iyy="1.87169" iyz="0.00460" izz="1.28440"/>
    </inertial>
    <visual>
      <origin rpy="0 0 0" xyz="0.0 0.0 -0.02718"/>
      <geometry>
        <mesh filename="package://ballbot_arm_description/meshes/v2020/link_upperarm.stl"/>
      </geometry>
      <material name="brown"/>
    </visual>
    <collision>
      <origin rpy="0 0 0" xyz="0.0 0.0 -0.05525"/>
      <geometry>
        <cylinder length="0.1105" radius="0.05"/>
      </geometry>
    </collision>
  </link>
  <link name="RArm4">
    <inertial>
      <origin xyz="0.00069 0.00003 -0.03966"/>
      <mass value="1.47100"/>
      <inertia ixx="1.84769" ixy="-0.00110" ixz="-0.07294" iyy="1.87169" iyz="0.00460" izz="1.28440"/>
    </inertial>
    <visual>
      <origin rpy="0 0 0" xyz="0.0 0.0 0.0"/>
      <geometry>
        <mesh filename="package://ballbot_arm_description/meshes/v2020/link_forearm_r.stl"/>
      </geometry>
      <material name="grey"/>
    </visual>
    <collision>
      <origin rpy="0 0 0" xyz="0.0 0.0 -0.05525"/>
      <geometry>
        <cylinder length="0.1105" radius="0.05"/>
      </geometry>
    </collision>
  </link>
  <link name="RArm5">
    <inertial>
      <origin xyz="0.00055 -0.00009 -0.03811"/>
      <mass value="0.75700"/>
      <inertia ixx="1.37630" ixy="-0.00120" ixz="-0.04232" iyy="1.38480" iyz="-0.00140" izz="0.50580"/>
    </inertial>
    <visual>
      <origin rpy="0 0 0" xyz="0.0 0.0 0.0"/>
      <geometry>
        <mesh filename="package://ballbot_arm_description/meshes/v2020/link_forearm_2_wrist.stl"/>
      </geometry>
      <material name="brown"/>
    </visual>
    <collision>
      <origin rpy="0 0 0" xyz="0.0 0.0 -0.05525"/>
      <geometry>
        <cylinder length="0.1105" radius="0.05"/>
      </geometry>
    </collision>
  </link>
  <link name="RArm6">
    <inertial>
      <origin xyz="0.00055 -0.00009 -0.03811"/>
      <mass value="0.75700"/>
      <inertia ixx="1.37630" ixy="-0.00120" ixz="-0.04232" iyy="1.38480" iyz="-0.00140" izz="0.50580"/>
    </inertial>
    <visual>
      <origin rpy="0 0 0" xyz="0.0 0.0 0.0"/>
      <geometry>
        <mesh filename="package://ballbot_arm_description/meshes/v2020/link_wrist_mid.stl"/>
      </geometry>
      <material name="grey"/>
    </visual>
    <collision>
      <origin rpy="0 0 0" xyz="0.0 0.0 -0.05525"/>
      <geometry>
        <cylinder length="0.1105" radius="0.05"/>
      </geometry>
    </collision>
  </link>
  <link name="RArm7">
    <inertial>
      <origin xyz="0.00055 -0.00009 -0.03811"/>
      <mass value="0.75700"/>
      <inertia ixx="1.37630" ixy="-0.00120" ixz="-0.04232" iyy="1.38480" iyz="-0.00140" izz="0.50580"/>
    </inertial>
    <visual>
      <origin rpy="0 0 0" xyz="0.0 0.0 0.0"/>
      <geometry>
        <mesh filename="package://ballbot_arm_description/meshes/v2020/link_wrist_2_hand.stl"/>
      </geometry>
      <material name="brown"/>
    </visual>
    <collision>
      <origin rpy="0 0 0" xyz="0.0 0.0 -0.05525"/>
      <geometry>
        <cylinder length="0.1105" radius="0.05"/>
      </geometry>
    </collision>
  </link>
  <joint name="Joint1" type="prismatic">
    <origin rpy="3.141592653589793 1.570796282091413 3.141592653589793" xyz="0.00000 0.00000 0.105838"/>
    <parent link="BallbotBase"/>
    <child link="Link_FakeBall"/>
    <limit effort="30" lower="-5" upper="5" velocity="1.0"/>
    <axis xyz="0 0 1"/>
  </joint>
  <joint name="Joint2" type="prismatic">
    <origin rpy="-1.5707963705062866 0.0 -0.0" xyz="0.00000 0.00000 0.00000"/>
    <parent link="Link_FakeBall"/>
    <child link="Link_Ball"/>
    <limit effort="30" lower="-5" upper="5" velocity="1.0"/>
    <axis xyz="0 0 1"/>
  </joint>
  <joint name="Joint3" type="revolute">
    <origin rpy="0.0 0.0 0.0" xyz="0.00000 0.00000 0.00000"/>
    <parent link="Link_Ball"/>
    <child link="Link_FakeBody"/>
    <limit effort="30" lower="-1.09662271123" upper="1.09662271123" velocity="1.0"/>
    <axis xyz="0 0 1"/>
  </joint>
  <joint name="Joint4" type="revolute">
    <origin rpy="1.5707963705062866 -0.0 0.0" xyz="0.00000 0.00000 0.00000"/>
    <parent link="Link_FakeBody"/>
    <child link="Link_Body"/>
    <limit effort="30" lower="-0.349065850399" upper="1.09662271123" velocity="1.0"/>
    <axis xyz="0 0 1"/>
  </joint>
  <joint name="JLA0" type="fixed">
    <origin rpy="1.57079632679 0.0 -3.14159265359" xyz="-1.32915 0.12314 -0.00635"/>
    <parent link="Link_Body"/>
    <child link="LArm0"/>
    <axis xyz="0 0 1"/>
  </joint>
  <joint name="JLA1" type="revolute">
    <!--<origin xyz="-1.32915 0.12314 -0.00635" rpy="${PI/2} 0.0 ${-PI}"/>
        <parent link="Link_Body"/>-->
    <origin rpy="0.0 0.0 0.0" xyz="0.0 0.0 0.0"/>
    <parent link="LArm0"/>
    <child link="LArm1"/>
    <limit effort="30" lower="-3.14159265359" upper="3.14159265359" velocity="1.0"/>
    <axis xyz="0 0 1"/>
  </joint>
  <joint name="JLA2" type="revolute">
    <origin rpy="1.5707963705062866 -0.0 0.0" xyz="0.00000 -0.05436 0.14900"/>
    <parent link="LArm1"/>
    <child link="LArm2"/>
    <limit effort="30" lower="-1.57079632679" upper="0.0" velocity="1.0"/>
    <axis xyz="0 0 1"/>
    <dynamics damping="1.0" friction="1.0"/>
  </joint>
  <joint name="JLA3" type="revolute">
    <origin rpy="2.0344439357957036 1.5707962290814481 -1.1071487177940917" xyz="-0.17786 0.00000 -0.05436"/>
    <parent link="LArm2"/>
    <child link="LArm3"/>
    <limit effort="30" lower="-3.14159265359" upper="3.14159265359" velocity="1.0"/>
    <axis xyz="0 0 1"/>
    <dynamics damping="1.0" friction="1.0"/>
  </joint>
  <joint name="JLA4" type="revolute">
    <origin rpy="-2.3561944901923457 1.5707962635746238 2.3561944901923457" xyz="0.00000 -0.05436 0.08522"/>
    <parent link="LArm3"/>
    <child link="LArm4"/>
    <limit effort="30" lower="-2.26892802759" upper="0.0" velocity="1.0"/>
    <axis xyz="0 0 1"/>
    <dynamics damping="1.0" friction="1.0"/>
  </joint>
  <joint name="JLA5" type="revolute">
    <origin rpy="-1.5707963705062866 4.371139000186238E-8 1.5707963267948948" xyz="-0.13200 -0.07000 -0.05073"/>
    <parent link="LArm4"/>
    <child link="LArm5"/>
    <limit effort="30" lower="-3.14159265359" upper="3.14159265359" velocity="1.0"/>
    <axis xyz="0 0 1"/>
    <dynamics damping="1.0" friction="1.0"/>
  </joint>
  <joint name="JLA6" type="revolute">
    <origin rpy="2.3561944901923457 1.5707962635746238 -2.3561944901923457" xyz="0.00000 0.04150 0.06000"/>
    <parent link="LArm5"/>
    <child link="LArm6"/>
    <limit effort="30" lower="-1.57079632679" upper="1.57079632679" velocity="1.0"/>
    <axis xyz="0 0 1"/>
    <dynamics damping="1.0" friction="1.0"/>
  </joint>
  <joint name="JLA7" type="revolute">
    <origin rpy="-1.5707963705062866 0.0 -0.0" xyz="-0.10750 0.04650 -0.04150"/>
    <parent link="LArm6"/>
    <child link="LArm7"/>
    <limit effort="30" lower="-1.57079632679" upper="1.57079632679" velocity="1.0"/>
    <axis xyz="0 0 1"/>
    <dynamics damping="1.0" friction="1.0"/>
  </joint>
  <joint name="JRA0" type="fixed">
    <origin rpy="-1.57079632679 0.0 3.14159265359" xyz="-1.32915 -0.12314 -0.00635"/>
    <parent link="Link_Body"/>
    <child link="RArm0"/>
    <axis xyz="0 0 1"/>
  </joint>
  <joint name="JRA1" type="revolute">
    <!--<origin xyz="-1.32915 -0.12314 -0.00635" rpy="${-PI/2} 0.0 ${PI}"/>
        <parent link="Link_Body"/>-->
    <origin rpy="0.0 0.0 0.0" xyz="0.0 0.0 0.0"/>
    <parent link="RArm0"/>
    <child link="RArm1"/>
    <limit effort="30" lower="-3.14159265359" upper="3.14159265359" velocity="1.0"/>
    <axis xyz="0 0 1"/>
    <dynamics damping="1.0" friction="1.0"/>
  </joint>
  <joint name="JRA2" type="revolute">
    <origin rpy="-1.5707963705062866 0.0 -0.0" xyz="0.00000 0.05436 0.14900"/>
    <parent link="RArm1"/>
    <child link="RArm2"/>
    <limit effort="30" lower="0.0" upper="1.57079632679" velocity="1.0"/>
    <axis xyz="0 0 1"/>
    <dynamics damping="1.0" friction="1.0"/>
  </joint>
  <joint name="JRA3" type="revolute">
    <origin rpy="3.141592653589793 -1.570796282091413 3.141592653589793" xyz="-0.17786 0.00000 -0.05436"/>
    <parent link="RArm2"/>
    <child link="RArm3"/>
    <limit effort="30" lower="-3.14159265359" upper="3.14159265359" velocity="1.0"/>
    <axis xyz="0 0 1"/>
    <dynamics damping="1.0" friction="1.0"/>
  </joint>
  <joint name="JRA4" type="revolute">
    <origin rpy="-2.3561944901923457 1.5707962635746238 2.3561944901923457" xyz="0.00000 -0.05436 0.08522"/>
    <parent link="RArm3"/>
    <child link="RArm4"/>
    <limit effort="30" lower="0.0" upper="2.26892802759" velocity="1.0"/>
    <axis xyz="0 0 1"/>
    <dynamics damping="1.0" friction="1.0"/>
  </joint>
  <joint name="JRA5" type="revolute">
    <!--<origin xyz="-0.13200 0.07000 -0.05073" rpy="-1.5707963705062866 4.371139000186238E-8 1.5707963267948948"/>-->
    <origin rpy="-1.57079632679 3.14159265359 1.57079632679" xyz="-0.13200 0.07000 -0.05073"/>
    <parent link="RArm4"/>
    <child link="RArm5"/>
    <limit effort="30" lower="-3.14159265359" upper="3.14159265359" velocity="1.0"/>
    <axis xyz="0 0 1"/>
    <dynamics damping="1.0" friction="1.0"/>
  </joint>
  <joint name="JRA6" type="revolute">
    <origin rpy="2.3561944901923457 1.5707962635746238 -2.3561944901923457" xyz="0.00000 0.04150 0.06000"/>
    <parent link="RArm5"/>
    <child link="RArm6"/>
    <limit effort="30" lower="-1.57079632679" upper="1.57079632679" velocity="1.0"/>
    <axis xyz="0 0 1"/>
    <dynamics damping="1.0" friction="1.0"/>
  </joint>
  <joint name="JRA7" type="revolute">
    <origin rpy="-1.5707963705062866 0.0 -0.0" xyz="-0.10750 0.04650 -0.04150"/>
    <parent link="RArm6"/>
    <child link="RArm7"/>
    <limit effort="30" lower="-1.57079632679" upper="1.57079632679" velocity="1.0"/>
    <axis xyz="0 0 1"/>
    <dynamics damping="1.0" friction="1.0"/>
  </joint>
  <!-- End-Effector frames -->
  <link name="toolR">
    </link>
  <joint name="RArm7-toolR" type="fixed">
    <origin rpy="0 1.57079632679 3.14159265359" xyz="-0.055 0 -0.04065"/>
    <axis xyz="0 0 1"/>
    <parent link="RArm7"/>
    <child link="toolR"/>
  </joint>
  <link name="toolL">
    </link>
  <joint name="LArm7-toolL" type="fixed">
    <origin rpy="0 -1.57079632679 0" xyz="-0.055 0 -0.04065"/>
    <parent link="LArm7"/>
    <child link="toolL"/>
  </joint>
  <link name="turret_pan">
    <visual>
      <origin rpy="0 0 0" xyz="0.0 0.0 0.0"/>
      <geometry>
        <mesh filename="package://ballbot_arm_description/meshes/v2020/turret_pan.stl"/>
      </geometry>
      <material name="grey"/>
    </visual>
  </link>
  <joint name="JTurret_Pan" type="fixed">
    <origin rpy="0 -1.57079632679 0" xyz="-1.405 0 0"/>
    <parent link="Link_Body"/>
    <child link="turret_pan"/>
    <limit effort="30" lower="-3.14159265359" upper="3.14159265359" velocity="1.0"/>
    <axis xyz="0 0 1"/>
    <dynamics damping="1.0" friction="1.0"/>
  </joint>
  <link name="turret_tilt">
    <visual>
      <origin rpy="0 0 0" xyz="0.0 0.0 0.0"/>
      <geometry>
        <mesh filename="package://ballbot_arm_description/meshes/v2020/turret_tilt.stl"/>
      </geometry>
      <material name="brown"/>
    </visual>
  </link>
  <joint name="JTurret_Tilt" type="fixed">
    <origin rpy="1.57079632679 0 3.14159265359" xyz="0.15557 -0.0347980 0.0541020"/>
    <parent link="turret_pan"/>
    <child link="turret_tilt"/>
    <limit effort="30" lower="0" upper="1.57079632679" velocity="1.0"/>
    <axis xyz="0 0 1"/>
    <dynamics damping="1.0" friction="1.0"/>
  </joint>
  <joint name="JL_D435_Mount" type="fixed">
    <origin rpy="0 0 0" xyz="0 0 0.0"/>
    <axis xyz="0 0 1"/>
    <parent link="toolL"/>
    <child link="L_D435_Mount"/>
  </joint>
  <link name="L_D435_Mount">
    <visual>
      <origin rpy="0 0 0" xyz="0 0 0"/>
      <geometry>
        <mesh filename="package://ballbot_arm_description/meshes/intelrealsense_mount.stl"/>
      </geometry>
      <material name="grey"/>
    </visual>
    <collision>
      <origin rpy="0 0 0" xyz="0 0 0"/>
      <geometry>
        <mesh filename="package://ballbot_arm_description/meshes/intelrealsense_mount.stl"/>
      </geometry>
    </collision>
    <inertial>
      <origin rpy="0 0 0" xyz="0 0 0"/>
      <mass value="0.001"/>
      <inertia ixx="1e-10" ixy="0.0" ixz="0.0" iyy="1e-10" iyz="0.0" izz="1e-10"/>
    </inertial>
  </link>
  <!-- camera body, with origin at bottom screw mount -->
  <joint name="LD435_camera_joint" type="fixed">
    <origin rpy="0.0 -1.3962634016 0.0 " xyz="-0.064427 0 0.016981"/>
    <parent link="L_D435_Mount"/>
    <child link="LD435_camera_bottom_screw_frame"/>
  </joint>
  <link name="LD435_camera_bottom_screw_frame"/>
  <joint name="LD435_camera_link_joint" type="fixed">
    <origin rpy="0 0 0" xyz="0 0.0175 0.0125"/>
    <parent link="LD435_camera_bottom_screw_frame"/>
    <child link="LD435_camera_link"/>
  </joint>
  <link name="LD435_camera_link">
    <visual>
      <origin rpy="1.57079632679 0 1.57079632679" xyz="0.0149 -0.0175 0"/>
      <geometry>
        <!-- <box size="${d435_cam_width} ${d435_cam_height} ${d435_cam_depth}"/> -->
        <mesh filename="package://realsense2_description/meshes/d435.dae"/>
      </geometry>
    </visual>
    <collision>
      <origin rpy="0 0 0" xyz="0 -0.0175 0"/>
      <geometry>
        <box size="0.02505 0.09 0.025"/>
      </geometry>
    </collision>
    <inertial>
      <!-- The following are not reliable values, and should not be used for modeling -->
      <mass value="0.564"/>
      <origin xyz="0 0 0"/>
      <inertia ixx="0.003881243" ixy="0.0" ixz="0.0" iyy="0.000498940" iyz="0.0" izz="0.003879257"/>
    </inertial>
  </link>
  <!-- Use the nominal extrinsics between camera frames if the calibrated extrinsics aren't being published. e.g. running the device in simulation  -->
  <joint name="JL_B4277" type="fixed">
    <origin rpy="0 0 0" xyz="0 0 0.006"/>
    <axis xyz="0 0 1"/>
    <parent link="L_D435_Mount"/>
    <child link="L_B4277_link"/>
  </joint>
  <link name="L_B4277_link">
    <visual>
      <origin rpy="0 0 0" xyz="0 0 0"/>
      <geometry>
        <mesh filename="package://ballbot_arm_description/meshes/link_B4277.stl"/>
      </geometry>
      <material name="blue"/>
    </visual>
    <collision>
      <origin rpy="0 0 0" xyz="0 0 0"/>
      <geometry>
        <mesh filename="package://ballbot_arm_description/meshes/link_B4277.stl"/>
      </geometry>
    </collision>
    <inertial>
      <origin rpy="0 0 0" xyz="0 0 0"/>
      <mass value="0.0001"/>
      <inertia ixx="1e-10" ixy="0.0" ixz="0.00" iyy="1e-10" iyz="0.0" izz="1e-10"/>
    </inertial>
  </link>
  <joint name="L_bh_base_joint" type="fixed">
    <origin rpy="0 0 1.57079632679" xyz="0 0 0.008"/>
    <parent link="L_B4277_link"/>
    <child link="L_bh_base_link"/>
  </joint>
  <!-- HAND BASE_LINK (RED) -->
  <link name="L_bh_base_link">
    <inertial>
      <mass value="3.0"/>
      <origin xyz="0 0 0"/>
      <inertia ixx="1.0" ixy="0.0" ixz="0.0" iyy="1.0" iyz="0.0" izz="1.0"/>
    </inertial>
    <visual>
      <origin rpy="0 0 0" xyz="0 0 0"/>
      <geometry>
        <mesh filename="package://barrett_hand_description/meshes/palm_282.dae"/>
      </geometry>
      <material name="Grey">
        <color rgba="0.75 0.75 0.75 1.0"/>
      </material>
    </visual>
    <collision>
      <origin rpy="0 0 0 " xyz="0 0 0"/>
      <geometry>
        <mesh filename="package://barrett_hand_description/meshes/palm_282.dae"/>
      </geometry>
      <contact_coefficients kd="1.0" kp="1000.0" mu="0"/>
    </collision>
  </link>
  <!-- finger 3 -->
  <!-- finger 31 link -->
  <link name="L_bh_finger_31_link">
    <inertial>
      <mass value="0.1"/>
      <origin rpy="0 0 0" xyz="-0.046 0 0"/>
      <inertia ixx="0.01" ixy="0" ixz="0" iyy="0.01" iyz="0" izz="0.01"/>
    </inertial>
    <visual>
      <origin rpy="0 0 0" xyz="-0.04 0 0"/>
      <geometry>
        <mesh filename="package://barrett_hand_description/meshes/knuckle_fixed.dae"/>
      </geometry>
      <material name="Black"/>
    </visual>
    <collision>
      <origin rpy="0 0 0" xyz="-0.04 0 0"/>
      <geometry>
        <mesh filename="package://barrett_hand_description/meshes/knuckle_fixed.dae"/>
      </geometry>
      <contact_coefficients kd="1.0" kp="1000.0" mu="0"/>
    </collision>
  </link>
  <!-- joint between BH_palm_link and BH_finger_31_link -->
  <!-- finger3 is the center finger and is fixed -->
  <joint name="L_bh_j31_joint" type="fixed">
    <parent link="L_bh_base_link"/>
    <child link="L_bh_finger_31_link"/>
    <origin rpy="0 0 -1.570796327" xyz="0 0 0.0252"/>
  </joint>
  <!-- finger 32 link -->
  <link name="L_bh_finger_32_link">
    <inertial>
      <mass value="0.1"/>
      <origin rpy="0 0 0" xyz="0 0 0"/>
      <inertia ixx="0.01" ixy="0" ixz="0" iyy="0.01" iyz="0" izz="0.01"/>
    </inertial>
    <visual>
      <origin rpy="0 0 0" xyz="0 0 0"/>
      <geometry>
        <mesh filename="package://barrett_hand_description/meshes/finger.dae"/>
      </geometry>
      <material name="Blue"/>
    </visual>
    <collision>
      <origin rpy="0 0 0" xyz="0 0 0"/>
      <geometry>
        <mesh filename="package://barrett_hand_description/meshes/finger.dae"/>
      </geometry>
      <contact_coefficients kd="1.0" kp="1000.0" mu="0"/>
    </collision>
  </link>
  <!-- joint between BH_finger_31_link and BH_finger_32_link -->
  <joint name="L_bh_j32_joint" type="fixed">
    <parent link="L_bh_finger_31_link"/>
    <child link="L_bh_finger_32_link"/>
    <origin rpy="1.5708 1 0" xyz="-0.05 0 0.0339"/>
    <axis xyz="0 0 -1"/>
    <limit effort="30.0" lower="0.0" upper="2.44" velocity="2.0"/>
    <dynamics damping="100.0" friction="1.0"/>
  </joint>
  <transmission name="L_bh_j32_transmission">
    <type>transmission_interface/SimpleTransmission</type>
    <joint name="L_bh_j32_joint">
      <hardwareInterface>PositionJointInterface</hardwareInterface>
    </joint>
    <actuator name="L_bh_j32">
      <hardwareInterface>PositionJointInterface</hardwareInterface>
      <mechanicalReduction>1</mechanicalReduction>
      <motorTorqueConstant>1</motorTorqueConstant>
    </actuator>
  </transmission>
  <!-- finger 33 link -->
  <link name="L_bh_finger_33_link">
    <inertial>
      <mass value="0.1"/>
      <origin rpy="0 0 0" xyz="0 0 0"/>
      <inertia ixx="0.01" ixy="0" ixz="0" iyy="0.01" iyz="0" izz="0.01"/>
    </inertial>
    <visual>
      <origin rpy="0 0 0" xyz="0 0 0"/>
      <geometry>
        <mesh filename="package://barrett_hand_description/meshes/finger_tip.dae"/>
      </geometry>
      <material name="Blue"/>
    </visual>
    <collision>
      <origin rpy="0 0 0" xyz="0 0 0"/>
      <geometry>
        <mesh filename="package://barrett_hand_description/meshes/finger_tip.dae"/>
      </geometry>
      <contact_coefficients kd="1.0" kp="1000.0" mu="0"/>
    </collision>
  </link>
  <!-- joint between BH_finger_32_link and BH_finger_33_link -->
  <joint name="L_bh_j33_joint" type="fixed">
    <parent link="L_bh_finger_32_link"/>
    <child link="L_bh_finger_33_link"/>
    <origin rpy="0 0 -0.5" xyz="-0.069936 0.003 0"/>
    <axis xyz="0 0 -1"/>
    <mimic joint="L_bh_j32_joint" multiplier="0.344262295082"/>
    <limit effort="30.0" lower="0.0" upper="0.84" velocity="2.0"/>
    <dynamics damping="100.0" friction="1.0"/>
  </joint>
  <transmission name="L_bh_j33_transmission">
    <type>transmission_interface/SimpleTransmission</type>
    <joint name="L_bh_j33_joint">
      <hardwareInterface>PositionJointInterface</hardwareInterface>
    </joint>
    <actuator name="L_bh_j33">
      <hardwareInterface>PositionJointInterface</hardwareInterface>
      <mechanicalReduction>1</mechanicalReduction>
      <motorTorqueConstant>1</motorTorqueConstant>
    </actuator>
  </transmission>
  <!-- finger 1 -->
  <!-- finger 11 link -->
  <link name="L_bh_finger_11_link">
    <inertial>
      <mass value="0.1"/>
      <origin rpy="0 0 0" xyz="-0.046 0 0"/>
      <inertia ixx="0.01" ixy="0" ixz="0" iyy="0.01" iyz="0" izz="0.01"/>
    </inertial>
    <visual>
      <origin rpy="0 0 0" xyz="0 0 0"/>
      <geometry>
        <mesh filename="package://barrett_hand_description/meshes/knuckle.dae"/>
      </geometry>
      <material name="Green"/>
    </visual>
    <collision>
      <origin rpy="0 0 0" xyz="0 0 0"/>
      <geometry>
        <mesh filename="package://barrett_hand_description/meshes/knuckle.dae"/>
      </geometry>
    </collision>
  </link>
  <!-- joint between BH_palm_link and BH_finger_11_link -->
  <joint name="L_bh_j11_joint" type="fixed">
    <parent link="L_bh_base_link"/>
    <child link="L_bh_finger_11_link"/>
    <origin rpy="0 0 1.5708" xyz="-0.025 0 0.0252"/>
    <axis xyz="0 0 -1"/>
    <limit effort="30.0" lower="0" upper="3.1416" velocity="2.0"/>
    <dynamics damping="100.0" friction="1.0"/>
  </joint>
  <transmission name="L_bh_j11_transmission">
    <type>transmission_interface/SimpleTransmission</type>
    <joint name="L_bh_j11_joint">
      <hardwareInterface>PositionJointInterface</hardwareInterface>
    </joint>
    <actuator name="L_bh_j11">
      <hardwareInterface>PositionJointInterface</hardwareInterface>
      <mechanicalReduction>1</mechanicalReduction>
      <motorTorqueConstant>1</motorTorqueConstant>
    </actuator>
  </transmission>
  <!-- finger 12 link -->
  <link name="L_bh_finger_12_link">
    <inertial>
      <mass value="0.1"/>
      <origin rpy="0 0 0" xyz="0 0 0"/>
      <inertia ixx="0.01" ixy="0" ixz="0" iyy="0.01" iyz="0" izz="0.01"/>
    </inertial>
    <visual>
      <origin rpy="0 0 0" xyz="0 0 0"/>
      <geometry>
        <mesh filename="package://barrett_hand_description/meshes/finger.dae"/>
      </geometry>
      <material name="Blue"/>
    </visual>
    <collision>
      <origin rpy="0 0 0" xyz="0 0 0"/>
      <geometry>
        <mesh filename="package://barrett_hand_description/meshes/finger.dae"/>
      </geometry>
      <contact_coefficients kd="1.0" kp="1000.0" mu="0"/>
    </collision>
  </link>
  <!-- joint between BH_finger_11_link and BH_finger_12_link -->
  <joint name="L_bh_j12_joint" type="fixed">
    <parent link="L_bh_finger_11_link"/>
    <child link="L_bh_finger_12_link"/>
    <origin rpy="1.5708 1 0" xyz="-0.05 0 0.0339"/>
    <axis xyz="0 0 -1"/>
    <limit effort="30.0" lower="0.0" upper="2.44" velocity="2.0"/>
    <dynamics damping="100.0" friction="1.0"/>
  </joint>
  <transmission name="L_bh_j12_transmission">
    <type>transmission_interface/SimpleTransmission</type>
    <joint name="L_bh_j12_joint">
      <hardwareInterface>PositionJointInterface</hardwareInterface>
    </joint>
    <actuator name="L_bh_j12">
      <hardwareInterface>PositionJointInterface</hardwareInterface>
      <mechanicalReduction>1</mechanicalReduction>
      <motorTorqueConstant>1</motorTorqueConstant>
    </actuator>
  </transmission>
  <!-- finger 13 link -->
  <link name="L_bh_finger_13_link">
    <inertial>
      <mass value="0.1"/>
      <origin rpy="0 0 0" xyz="0 0 0"/>
      <inertia ixx="0.01" ixy="0" ixz="0" iyy="0.01" iyz="0" izz="0.01"/>
    </inertial>
    <visual>
      <origin rpy="0 0 0" xyz="0 0 0"/>
      <geometry>
        <mesh filename="package://barrett_hand_description/meshes/finger_tip.dae"/>
      </geometry>
      <material name="Blue"/>
    </visual>
    <collision>
      <origin rpy="0 0 0" xyz="0 0 0"/>
      <geometry>
        <mesh filename="package://barrett_hand_description/meshes/finger_tip.dae"/>
      </geometry>
      <contact_coefficients kd="1.0" kp="1000.0" mu="0"/>
    </collision>
  </link>
  <!-- joint between BH_finger_12_link and BH_finger_13_link -->
  <joint name="L_bh_j13_joint" type="fixed">
    <parent link="L_bh_finger_12_link"/>
    <child link="L_bh_finger_13_link"/>
    <origin rpy="0 0 -0.5" xyz="-0.069936 0.003 0"/>
    <axis xyz="0 0 -1"/>
    <mimic joint="L_bh_j12_joint" multiplier="0.344262295082"/>
    <limit effort="30.0" lower="0.0" upper="0.84" velocity="2.0"/>
    <dynamics damping="100.0" friction="1.0"/>
  </joint>
  <transmission name="L_bh_j13_transmission">
    <type>transmission_interface/SimpleTransmission</type>
    <joint name="L_bh_j13_joint">
      <hardwareInterface>PositionJointInterface</hardwareInterface>
    </joint>
    <actuator name="L_bh_j13">
      <hardwareInterface>PositionJointInterface</hardwareInterface>
      <mechanicalReduction>1</mechanicalReduction>
      <motorTorqueConstant>1</motorTorqueConstant>
    </actuator>
  </transmission>
  <!-- finger 2 -->
  <!-- finger 21 link -->
  <link name="L_bh_finger_21_link">
    <inertial>
      <mass value="0.1"/>
      <origin rpy="0 0 0" xyz="-0.046 0 0"/>
      <inertia ixx="0.01" ixy="0" ixz="0" iyy="0.01" iyz="0" izz="0.01"/>
    </inertial>
    <visual>
      <origin rpy="0 0 0" xyz="0 0 0"/>
      <geometry>
        <mesh filename="package://barrett_hand_description/meshes/knuckle.dae"/>
      </geometry>
      <material name="Green"/>
    </visual>
    <collision>
      <origin rpy="0 0 0" xyz="0 0 0"/>
      <geometry>
        <mesh filename="package://barrett_hand_description/meshes/knuckle.dae"/>
      </geometry>
    </collision>
  </link>
  <!-- joint between BH_palm_link and BH_finger_21_link -->
  <joint name="L_bh_j21_joint" type="fixed">
    <parent link="L_bh_base_link"/>
    <child link="L_bh_finger_21_link"/>
    <origin rpy="0 0 1.5708" xyz="0.025 0 0.0252"/>
    <axis xyz="0 0 1"/>
    <mimic joint="L_bh_j11_joint" multiplier="1"/>
    <limit effort="30.0" lower="0" upper="3.1416" velocity="2.0"/>
    <dynamics damping="100.0" friction="1.0"/>
  </joint>
  <transmission name="L_bh_j21_transmission">
    <type>transmission_interface/SimpleTransmission</type>
    <joint name="L_bh_j21_joint">
      <hardwareInterface>PositionJointInterface</hardwareInterface>
    </joint>
    <actuator name="L_bh_j21">
      <hardwareInterface>PositionJointInterface</hardwareInterface>
      <mechanicalReduction>1</mechanicalReduction>
      <motorTorqueConstant>1</motorTorqueConstant>
    </actuator>
  </transmission>
  <!-- finger 12 link -->
  <link name="L_bh_finger_22_link">
    <inertial>
      <mass value="0.1"/>
      <origin rpy="0 0 0" xyz="0 0 0"/>
      <inertia ixx="0.01" ixy="0" ixz="0" iyy="0.01" iyz="0" izz="0.01"/>
    </inertial>
    <visual>
      <origin rpy="0 0 0" xyz="0 0 0"/>
      <geometry>
        <mesh filename="package://barrett_hand_description/meshes/finger.dae"/>
      </geometry>
      <material name="Blue"/>
    </visual>
    <collision>
      <origin rpy="0 0 0" xyz="0 0 0"/>
      <geometry>
        <mesh filename="package://barrett_hand_description/meshes/finger.dae"/>
      </geometry>
      <contact_coefficients kd="1.0" kp="1000.0" mu="0"/>
    </collision>
  </link>
  <!-- joint between BH_finger_21_link and BH_finger_22_link -->
  <joint name="L_bh_j22_joint" type="fixed">
    <parent link="L_bh_finger_21_link"/>
    <child link="L_bh_finger_22_link"/>
    <origin rpy="1.5708 1.0 0" xyz="-0.05 0 0.0339"/>
    <axis xyz="0 0 -1"/>
    <limit effort="30.0" lower="0.0" upper="2.44" velocity="2.0"/>
    <dynamics damping="100.0" friction="1.0"/>
  </joint>
  <transmission name="L_bh_j22_transmission">
    <type>transmission_interface/SimpleTransmission</type>
    <joint name="L_bh_j22_joint">
      <hardwareInterface>PositionJointInterface</hardwareInterface>
    </joint>
    <actuator name="L_bh_j22">
      <hardwareInterface>PositionJointInterface</hardwareInterface>
      <mechanicalReduction>1</mechanicalReduction>
      <motorTorqueConstant>1</motorTorqueConstant>
    </actuator>
  </transmission>
  <!-- finger 23 link -->
  <link name="L_bh_finger_23_link">
    <inertial>
      <mass value="0.1"/>
      <origin rpy="0 0 0" xyz="0 0 0"/>
      <inertia ixx="0.01" ixy="0" ixz="0" iyy="0.01" iyz="0" izz="0.01"/>
    </inertial>
    <visual>
      <origin rpy="0 0 0" xyz="0 0 0"/>
      <geometry>
        <mesh filename="package://barrett_hand_description/meshes/finger_tip.dae"/>
      </geometry>
      <material name="Blue"/>
    </visual>
    <collision>
      <origin rpy="0 0 0" xyz="0 0 0"/>
      <geometry>
        <mesh filename="package://barrett_hand_description/meshes/finger_tip.dae"/>
      </geometry>
      <contact_coefficients kd="1.0" kp="1000.0" mu="0"/>
    </collision>
  </link>
  <!-- joint between BH_finger_22_link and BH_finger_23_link -->
  <joint name="L_bh_j23_joint" type="fixed">
    <parent link="L_bh_finger_22_link"/>
    <child link="L_bh_finger_23_link"/>
    <origin rpy="0 0 -0.5" xyz="-0.069936 0.003 0"/>
    <axis xyz="0 0 -1"/>
    <mimic joint="L_bh_j22_joint" multiplier="0.344262295082"/>
    <limit effort="30.0" lower="0.0" upper="0.84" velocity="2.0"/>
    <dynamics damping="100.0" friction="1.0"/>
  </joint>
  <transmission name="L_bh_j23_transmission">
    <type>transmission_interface/SimpleTransmission</type>
    <joint name="L_bh_j23_joint">
      <hardwareInterface>PositionJointInterface</hardwareInterface>
    </joint>
    <actuator name="L_bh_j23">
      <hardwareInterface>PositionJointInterface</hardwareInterface>
      <mechanicalReduction>1</mechanicalReduction>
      <motorTorqueConstant>1</motorTorqueConstant>
    </actuator>
  </transmission>
  <gazebo>
    <plugin filename="libgazebo_mimic_plugin.so" name="mimic_plugin">
      <joint>L_bh_j11_joint</joint>
      <mimicJoint>L_bh_j21_joint</mimicJoint>
      <multiplier>1</multiplier>
    </plugin>
  </gazebo>
  <gazebo>
    <plugin filename="libgazebo_mimic_plugin.so" name="mimic_plugin">
      <joint>L_bh_j12_joint</joint>
      <mimicJoint>L_bh_j13_joint</mimicJoint>
      <multiplier>0.344</multiplier>
    </plugin>
  </gazebo>
  <gazebo>
    <plugin filename="libgazebo_mimic_plugin.so" name="mimic_plugin">
      <joint>L_bh_j22_joint</joint>
      <mimicJoint>L_bh_j23_joint</mimicJoint>
      <multiplier>0.344</multiplier>
    </plugin>
  </gazebo>
  <gazebo>
    <plugin filename="libgazebo_mimic_plugin.so" name="mimic_plugin">
      <joint>L_bh_j32_joint</joint>
      <mimicJoint>L_bh_j33_joint</mimicJoint>
      <multiplier>0.344</multiplier>
    </plugin>
  </gazebo>
  <gazebo reference="L_bh_base_link">
    <material>Gazebo/White</material>
    <turnGravityOff>False</turnGravityOff>
  </gazebo>
  <gazebo reference="L_bh_finger_31_link">
    <material>Gazebo/Grey</material>
    <turnGravityOff>False</turnGravityOff>
  </gazebo>
  <gazebo reference="L_bh_finger_32_link">
    <material>Gazebo/Grey</material>
    <turnGravityOff>False</turnGravityOff>
  </gazebo>
  <gazebo reference="L_bh_finger_33_link">
    <material>Gazebo/Grey</material>
    <turnGravityOff>False</turnGravityOff>
  </gazebo>
  <gazebo reference="L_bh_finger_11_link">
    <material>Gazebo/Grey</material>
    <turnGravityOff>False</turnGravityOff>
  </gazebo>
  <gazebo reference="L_bh_finger_12_link">
    <material>Gazebo/Grey</material>
    <turnGravityOff>False</turnGravityOff>
  </gazebo>
  <gazebo reference="L_bh_finger_13_link">
    <material>Gazebo/Grey</material>
    <turnGravityOff>False</turnGravityOff>
  </gazebo>
  <gazebo reference="L_bh_finger_21_link">
    <material>Gazebo/Grey</material>
    <turnGravityOff>False</turnGravityOff>
  </gazebo>
  <gazebo reference="L_bh_finger_22_link">
    <material>Gazebo/Grey</material>
    <turnGravityOff>False</turnGravityOff>
  </gazebo>
  <gazebo reference="L_bh_finger_23_link">
    <material>Gazebo/Grey</material>
    <turnGravityOff>False</turnGravityOff>
  </gazebo>
  <joint name="JR_D435_Mount" type="fixed">
    <origin rpy="0 0 3.14159265359" xyz="0 0 0.0"/>
    <axis xyz="0 0 1"/>
    <parent link="toolR"/>
    <child link="R_D435_Mount"/>
  </joint>
  <link name="R_D435_Mount">
    <visual>
      <origin rpy="0 0 0" xyz="0 0 0"/>
      <geometry>
        <mesh filename="package://ballbot_arm_description/meshes/intelrealsense_mount.stl"/>
      </geometry>
      <material name="grey"/>
    </visual>
    <collision>
      <origin rpy="0 0 0" xyz="0 0 0"/>
      <geometry>
        <mesh filename="package://ballbot_arm_description/meshes/intelrealsense_mount.stl"/>
      </geometry>
    </collision>
    <inertial>
      <origin rpy="0 0 0" xyz="0 0 0"/>
      <mass value="0.001"/>
      <inertia ixx="1e-10" ixy="0.0" ixz="0.0" iyy="1e-10" iyz="0.0" izz="1e-10"/>
    </inertial>
  </link>
  <!-- camera body, with origin at bottom screw mount -->
  <joint name="RD435_camera_joint" type="fixed">
    <origin rpy="0.0 -1.3962634016 0.0 " xyz="-0.064427 0 0.016981"/>
    <parent link="R_D435_Mount"/>
    <child link="RD435_camera_bottom_screw_frame"/>
  </joint>
  <link name="RD435_camera_bottom_screw_frame"/>
  <joint name="RD435_camera_link_joint" type="fixed">
    <origin rpy="0 0 0" xyz="0 0.0175 0.0125"/>
    <parent link="RD435_camera_bottom_screw_frame"/>
    <child link="RD435_camera_link"/>
  </joint>
  <link name="RD435_camera_link">
    <visual>
      <origin rpy="1.57079632679 0 1.57079632679" xyz="0.0149 -0.0175 0"/>
      <geometry>
        <!-- <box size="${d435_cam_width} ${d435_cam_height} ${d435_cam_depth}"/> -->
        <mesh filename="package://realsense2_description/meshes/d435.dae"/>
      </geometry>
    </visual>
    <collision>
      <origin rpy="0 0 0" xyz="0 -0.0175 0"/>
      <geometry>
        <box size="0.02505 0.09 0.025"/>
      </geometry>
    </collision>
    <inertial>
      <!-- The following are not reliable values, and should not be used for modeling -->
      <mass value="0.564"/>
      <origin xyz="0 0 0"/>
      <inertia ixx="0.003881243" ixy="0.0" ixz="0.0" iyy="0.000498940" iyz="0.0" izz="0.003879257"/>
    </inertial>
  </link>
  <!-- Use the nominal extrinsics between camera frames if the calibrated extrinsics aren't being published. e.g. running the device in simulation  -->
  <joint name="JR_B4277" type="fixed">
    <origin rpy="0 0 0" xyz="0 0 0.006"/>
    <axis xyz="0 0 1"/>
    <parent link="R_D435_Mount"/>
    <child link="R_B4277_link"/>
  </joint>
  <link name="R_B4277_link">
    <visual>
      <origin rpy="0 0 0" xyz="0 0 0"/>
      <geometry>
        <mesh filename="package://ballbot_arm_description/meshes/link_B4277.stl"/>
      </geometry>
      <material name="blue"/>
    </visual>
    <collision>
      <origin rpy="0 0 0" xyz="0 0 0"/>
      <geometry>
        <mesh filename="package://ballbot_arm_description/meshes/link_B4277.stl"/>
      </geometry>
    </collision>
    <inertial>
      <origin rpy="0 0 0" xyz="0 0 0"/>
      <mass value="0.0001"/>
      <inertia ixx="1e-10" ixy="0.0" ixz="0.00" iyy="1e-10" iyz="0.0" izz="1e-10"/>
    </inertial>
  </link>
  <joint name="R_bh_base_joint" type="fixed">
    <origin rpy="0 0 1.57079632679" xyz="0 0 0.008"/>
    <parent link="R_B4277_link"/>
    <child link="R_bh_base_link"/>
  </joint>
  <!-- HAND BASE_LINK (RED) -->
  <link name="R_bh_base_link">
    <inertial>
      <mass value="3.0"/>
      <origin xyz="0 0 0"/>
      <inertia ixx="1.0" ixy="0.0" ixz="0.0" iyy="1.0" iyz="0.0" izz="1.0"/>
    </inertial>
    <visual>
      <origin rpy="0 0 0" xyz="0 0 0"/>
      <geometry>
        <mesh filename="package://barrett_hand_description/meshes/palm_282.dae"/>
      </geometry>
      <material name="Grey">
        <color rgba="0.75 0.75 0.75 1.0"/>
      </material>
    </visual>
    <collision>
      <origin rpy="0 0 0 " xyz="0 0 0"/>
      <geometry>
        <mesh filename="package://barrett_hand_description/meshes/palm_282.dae"/>
      </geometry>
      <contact_coefficients kd="1.0" kp="1000.0" mu="0"/>
    </collision>
  </link>
  <!-- finger 3 -->
  <!-- finger 31 link -->
  <link name="R_bh_finger_31_link">
    <inertial>
      <mass value="0.1"/>
      <origin rpy="0 0 0" xyz="-0.046 0 0"/>
      <inertia ixx="0.01" ixy="0" ixz="0" iyy="0.01" iyz="0" izz="0.01"/>
    </inertial>
    <visual>
      <origin rpy="0 0 0" xyz="-0.04 0 0"/>
      <geometry>
        <mesh filename="package://barrett_hand_description/meshes/knuckle_fixed.dae"/>
      </geometry>
      <material name="Black"/>
    </visual>
    <collision>
      <origin rpy="0 0 0" xyz="-0.04 0 0"/>
      <geometry>
        <mesh filename="package://barrett_hand_description/meshes/knuckle_fixed.dae"/>
      </geometry>
      <contact_coefficients kd="1.0" kp="1000.0" mu="0"/>
    </collision>
  </link>
  <!-- joint between BH_palm_link and BH_finger_31_link -->
  <!-- finger3 is the center finger and is fixed -->
  <joint name="R_bh_j31_joint" type="fixed">
    <parent link="R_bh_base_link"/>
    <child link="R_bh_finger_31_link"/>
    <origin rpy="0 0 -1.570796327" xyz="0 0 0.0252"/>
  </joint>
  <!-- finger 32 link -->
  <link name="R_bh_finger_32_link">
    <inertial>
      <mass value="0.1"/>
      <origin rpy="0 0 0" xyz="0 0 0"/>
      <inertia ixx="0.01" ixy="0" ixz="0" iyy="0.01" iyz="0" izz="0.01"/>
    </inertial>
    <visual>
      <origin rpy="0 0 0" xyz="0 0 0"/>
      <geometry>
        <mesh filename="package://barrett_hand_description/meshes/finger.dae"/>
      </geometry>
      <material name="Blue"/>
    </visual>
    <collision>
      <origin rpy="0 0 0" xyz="0 0 0"/>
      <geometry>
        <mesh filename="package://barrett_hand_description/meshes/finger.dae"/>
      </geometry>
      <contact_coefficients kd="1.0" kp="1000.0" mu="0"/>
    </collision>
  </link>
  <!-- joint between BH_finger_31_link and BH_finger_32_link -->
  <joint name="R_bh_j32_joint" type="fixed">
    <parent link="R_bh_finger_31_link"/>
    <child link="R_bh_finger_32_link"/>
    <origin rpy="1.5708 1 0" xyz="-0.05 0 0.0339"/>
    <axis xyz="0 0 -1"/>
    <limit effort="30.0" lower="0.0" upper="2.44" velocity="2.0"/>
    <dynamics damping="100.0" friction="1.0"/>
  </joint>
  <transmission name="R_bh_j32_transmission">
    <type>transmission_interface/SimpleTransmission</type>
    <joint name="R_bh_j32_joint">
      <hardwareInterface>PositionJointInterface</hardwareInterface>
    </joint>
    <actuator name="R_bh_j32">
      <hardwareInterface>PositionJointInterface</hardwareInterface>
      <mechanicalReduction>1</mechanicalReduction>
      <motorTorqueConstant>1</motorTorqueConstant>
    </actuator>
  </transmission>
  <!-- finger 33 link -->
  <link name="R_bh_finger_33_link">
    <inertial>
      <mass value="0.1"/>
      <origin rpy="0 0 0" xyz="0 0 0"/>
      <inertia ixx="0.01" ixy="0" ixz="0" iyy="0.01" iyz="0" izz="0.01"/>
    </inertial>
    <visual>
      <origin rpy="0 0 0" xyz="0 0 0"/>
      <geometry>
        <mesh filename="package://barrett_hand_description/meshes/finger_tip.dae"/>
      </geometry>
      <material name="Blue"/>
    </visual>
    <collision>
      <origin rpy="0 0 0" xyz="0 0 0"/>
      <geometry>
        <mesh filename="package://barrett_hand_description/meshes/finger_tip.dae"/>
      </geometry>
      <contact_coefficients kd="1.0" kp="1000.0" mu="0"/>
    </collision>
  </link>
  <!-- joint between BH_finger_32_link and BH_finger_33_link -->
  <joint name="R_bh_j33_joint" type="fixed">
    <parent link="R_bh_finger_32_link"/>
    <child link="R_bh_finger_33_link"/>
    <origin rpy="0 0 -0.5" xyz="-0.069936 0.003 0"/>
    <axis xyz="0 0 -1"/>
    <mimic joint="R_bh_j32_joint" multiplier="0.344262295082"/>
    <limit effort="30.0" lower="0.0" upper="0.84" velocity="2.0"/>
    <dynamics damping="100.0" friction="1.0"/>
  </joint>
  <transmission name="R_bh_j33_transmission">
    <type>transmission_interface/SimpleTransmission</type>
    <joint name="R_bh_j33_joint">
      <hardwareInterface>PositionJointInterface</hardwareInterface>
    </joint>
    <actuator name="R_bh_j33">
      <hardwareInterface>PositionJointInterface</hardwareInterface>
      <mechanicalReduction>1</mechanicalReduction>
      <motorTorqueConstant>1</motorTorqueConstant>
    </actuator>
  </transmission>
  <!-- finger 1 -->
  <!-- finger 11 link -->
  <link name="R_bh_finger_11_link">
    <inertial>
      <mass value="0.1"/>
      <origin rpy="0 0 0" xyz="-0.046 0 0"/>
      <inertia ixx="0.01" ixy="0" ixz="0" iyy="0.01" iyz="0" izz="0.01"/>
    </inertial>
    <visual>
      <origin rpy="0 0 0" xyz="0 0 0"/>
      <geometry>
        <mesh filename="package://barrett_hand_description/meshes/knuckle.dae"/>
      </geometry>
      <material name="Green"/>
    </visual>
    <collision>
      <origin rpy="0 0 0" xyz="0 0 0"/>
      <geometry>
        <mesh filename="package://barrett_hand_description/meshes/knuckle.dae"/>
      </geometry>
    </collision>
  </link>
  <!-- joint between BH_palm_link and BH_finger_11_link -->
  <joint name="R_bh_j11_joint" type="fixed">
    <parent link="R_bh_base_link"/>
    <child link="R_bh_finger_11_link"/>
    <origin rpy="0 0 1.5708" xyz="-0.025 0 0.0252"/>
    <axis xyz="0 0 -1"/>
    <limit effort="30.0" lower="0" upper="3.1416" velocity="2.0"/>
    <dynamics damping="100.0" friction="1.0"/>
  </joint>
  <transmission name="R_bh_j11_transmission">
    <type>transmission_interface/SimpleTransmission</type>
    <joint name="R_bh_j11_joint">
      <hardwareInterface>PositionJointInterface</hardwareInterface>
    </joint>
    <actuator name="R_bh_j11">
      <hardwareInterface>PositionJointInterface</hardwareInterface>
      <mechanicalReduction>1</mechanicalReduction>
      <motorTorqueConstant>1</motorTorqueConstant>
    </actuator>
  </transmission>
  <!-- finger 12 link -->
  <link name="R_bh_finger_12_link">
    <inertial>
      <mass value="0.1"/>
      <origin rpy="0 0 0" xyz="0 0 0"/>
      <inertia ixx="0.01" ixy="0" ixz="0" iyy="0.01" iyz="0" izz="0.01"/>
    </inertial>
    <visual>
      <origin rpy="0 0 0" xyz="0 0 0"/>
      <geometry>
        <mesh filename="package://barrett_hand_description/meshes/finger.dae"/>
      </geometry>
      <material name="Blue"/>
    </visual>
    <collision>
      <origin rpy="0 0 0" xyz="0 0 0"/>
      <geometry>
        <mesh filename="package://barrett_hand_description/meshes/finger.dae"/>
      </geometry>
      <contact_coefficients kd="1.0" kp="1000.0" mu="0"/>
    </collision>
  </link>
  <!-- joint between BH_finger_11_link and BH_finger_12_link -->
  <joint name="R_bh_j12_joint" type="fixed">
    <parent link="R_bh_finger_11_link"/>
    <child link="R_bh_finger_12_link"/>
    <origin rpy="1.5708 1 0" xyz="-0.05 0 0.0339"/>
    <axis xyz="0 0 -1"/>
    <limit effort="30.0" lower="0.0" upper="2.44" velocity="2.0"/>
    <dynamics damping="100.0" friction="1.0"/>
  </joint>
  <transmission name="R_bh_j12_transmission">
    <type>transmission_interface/SimpleTransmission</type>
    <joint name="R_bh_j12_joint">
      <hardwareInterface>PositionJointInterface</hardwareInterface>
    </joint>
    <actuator name="R_bh_j12">
      <hardwareInterface>PositionJointInterface</hardwareInterface>
      <mechanicalReduction>1</mechanicalReduction>
      <motorTorqueConstant>1</motorTorqueConstant>
    </actuator>
  </transmission>
  <!-- finger 13 link -->
  <link name="R_bh_finger_13_link">
    <inertial>
      <mass value="0.1"/>
      <origin rpy="0 0 0" xyz="0 0 0"/>
      <inertia ixx="0.01" ixy="0" ixz="0" iyy="0.01" iyz="0" izz="0.01"/>
    </inertial>
    <visual>
      <origin rpy="0 0 0" xyz="0 0 0"/>
      <geometry>
        <mesh filename="package://barrett_hand_description/meshes/finger_tip.dae"/>
      </geometry>
      <material name="Blue"/>
    </visual>
    <collision>
      <origin rpy="0 0 0" xyz="0 0 0"/>
      <geometry>
        <mesh filename="package://barrett_hand_description/meshes/finger_tip.dae"/>
      </geometry>
      <contact_coefficients kd="1.0" kp="1000.0" mu="0"/>
    </collision>
  </link>
  <!-- joint between BH_finger_12_link and BH_finger_13_link -->
  <joint name="R_bh_j13_joint" type="fixed">
    <parent link="R_bh_finger_12_link"/>
    <child link="R_bh_finger_13_link"/>
    <origin rpy="0 0 -0.5" xyz="-0.069936 0.003 0"/>
    <axis xyz="0 0 -1"/>
    <mimic joint="R_bh_j12_joint" multiplier="0.344262295082"/>
    <limit effort="30.0" lower="0.0" upper="0.84" velocity="2.0"/>
    <dynamics damping="100.0" friction="1.0"/>
  </joint>
  <transmission name="R_bh_j13_transmission">
    <type>transmission_interface/SimpleTransmission</type>
    <joint name="R_bh_j13_joint">
      <hardwareInterface>PositionJointInterface</hardwareInterface>
    </joint>
    <actuator name="R_bh_j13">
      <hardwareInterface>PositionJointInterface</hardwareInterface>
      <mechanicalReduction>1</mechanicalReduction>
      <motorTorqueConstant>1</motorTorqueConstant>
    </actuator>
  </transmission>
  <!-- finger 2 -->
  <!-- finger 21 link -->
  <link name="R_bh_finger_21_link">
    <inertial>
      <mass value="0.1"/>
      <origin rpy="0 0 0" xyz="-0.046 0 0"/>
      <inertia ixx="0.01" ixy="0" ixz="0" iyy="0.01" iyz="0" izz="0.01"/>
    </inertial>
    <visual>
      <origin rpy="0 0 0" xyz="0 0 0"/>
      <geometry>
        <mesh filename="package://barrett_hand_description/meshes/knuckle.dae"/>
      </geometry>
      <material name="Green"/>
    </visual>
    <collision>
      <origin rpy="0 0 0" xyz="0 0 0"/>
      <geometry>
        <mesh filename="package://barrett_hand_description/meshes/knuckle.dae"/>
      </geometry>
    </collision>
  </link>
  <!-- joint between BH_palm_link and BH_finger_21_link -->
  <joint name="R_bh_j21_joint" type="fixed">
    <parent link="R_bh_base_link"/>
    <child link="R_bh_finger_21_link"/>
    <origin rpy="0 0 1.5708" xyz="0.025 0 0.0252"/>
    <axis xyz="0 0 1"/>
    <mimic joint="R_bh_j11_joint" multiplier="1"/>
    <limit effort="30.0" lower="0" upper="3.1416" velocity="2.0"/>
    <dynamics damping="100.0" friction="1.0"/>
  </joint>
  <transmission name="R_bh_j21_transmission">
    <type>transmission_interface/SimpleTransmission</type>
    <joint name="R_bh_j21_joint">
      <hardwareInterface>PositionJointInterface</hardwareInterface>
    </joint>
    <actuator name="R_bh_j21">
      <hardwareInterface>PositionJointInterface</hardwareInterface>
      <mechanicalReduction>1</mechanicalReduction>
      <motorTorqueConstant>1</motorTorqueConstant>
    </actuator>
  </transmission>
  <!-- finger 12 link -->
  <link name="R_bh_finger_22_link">
    <inertial>
      <mass value="0.1"/>
      <origin rpy="0 0 0" xyz="0 0 0"/>
      <inertia ixx="0.01" ixy="0" ixz="0" iyy="0.01" iyz="0" izz="0.01"/>
    </inertial>
    <visual>
      <origin rpy="0 0 0" xyz="0 0 0"/>
      <geometry>
        <mesh filename="package://barrett_hand_description/meshes/finger.dae"/>
      </geometry>
      <material name="Blue"/>
    </visual>
    <collision>
      <origin rpy="0 0 0" xyz="0 0 0"/>
      <geometry>
        <mesh filename="package://barrett_hand_description/meshes/finger.dae"/>
      </geometry>
      <contact_coefficients kd="1.0" kp="1000.0" mu="0"/>
    </collision>
  </link>
  <!-- joint between BH_finger_21_link and BH_finger_22_link -->
  <joint name="R_bh_j22_joint" type="fixed">
    <parent link="R_bh_finger_21_link"/>
    <child link="R_bh_finger_22_link"/>
    <origin rpy="1.5708 1.0 0" xyz="-0.05 0 0.0339"/>
    <axis xyz="0 0 -1"/>
    <limit effort="30.0" lower="0.0" upper="2.44" velocity="2.0"/>
    <dynamics damping="100.0" friction="1.0"/>
  </joint>
  <transmission name="R_bh_j22_transmission">
    <type>transmission_interface/SimpleTransmission</type>
    <joint name="R_bh_j22_joint">
      <hardwareInterface>PositionJointInterface</hardwareInterface>
    </joint>
    <actuator name="R_bh_j22">
      <hardwareInterface>PositionJointInterface</hardwareInterface>
      <mechanicalReduction>1</mechanicalReduction>
      <motorTorqueConstant>1</motorTorqueConstant>
    </actuator>
  </transmission>
  <!-- finger 23 link -->
  <link name="R_bh_finger_23_link">
    <inertial>
      <mass value="0.1"/>
      <origin rpy="0 0 0" xyz="0 0 0"/>
      <inertia ixx="0.01" ixy="0" ixz="0" iyy="0.01" iyz="0" izz="0.01"/>
    </inertial>
    <visual>
      <origin rpy="0 0 0" xyz="0 0 0"/>
      <geometry>
        <mesh filename="package://barrett_hand_description/meshes/finger_tip.dae"/>
      </geometry>
      <material name="Blue"/>
    </visual>
    <collision>
      <origin rpy="0 0 0" xyz="0 0 0"/>
      <geometry>
        <mesh filename="package://barrett_hand_description/meshes/finger_tip.dae"/>
      </geometry>
      <contact_coefficients kd="1.0" kp="1000.0" mu="0"/>
    </collision>
  </link>
  <!-- joint between BH_finger_22_link and BH_finger_23_link -->
  <joint name="R_bh_j23_joint" type="fixed">
    <parent link="R_bh_finger_22_link"/>
    <child link="R_bh_finger_23_link"/>
    <origin rpy="0 0 -0.5" xyz="-0.069936 0.003 0"/>
    <axis xyz="0 0 -1"/>
    <mimic joint="R_bh_j22_joint" multiplier="0.344262295082"/>
    <limit effort="30.0" lower="0.0" upper="0.84" velocity="2.0"/>
    <dynamics damping="100.0" friction="1.0"/>
  </joint>
  <transmission name="R_bh_j23_transmission">
    <type>transmission_interface/SimpleTransmission</type>
    <joint name="R_bh_j23_joint">
      <hardwareInterface>PositionJointInterface</hardwareInterface>
    </joint>
    <actuator name="R_bh_j23">
      <hardwareInterface>PositionJointInterface</hardwareInterface>
      <mechanicalReduction>1</mechanicalReduction>
      <motorTorqueConstant>1</motorTorqueConstant>
    </actuator>
  </transmission>
  <gazebo>
    <plugin filename="libgazebo_mimic_plugin.so" name="mimic_plugin">
      <joint>R_bh_j11_joint</joint>
      <mimicJoint>R_bh_j21_joint</mimicJoint>
      <multiplier>1</multiplier>
    </plugin>
  </gazebo>
  <gazebo>
    <plugin filename="libgazebo_mimic_plugin.so" name="mimic_plugin">
      <joint>R_bh_j12_joint</joint>
      <mimicJoint>R_bh_j13_joint</mimicJoint>
      <multiplier>0.344</multiplier>
    </plugin>
  </gazebo>
  <gazebo>
    <plugin filename="libgazebo_mimic_plugin.so" name="mimic_plugin">
      <joint>R_bh_j22_joint</joint>
      <mimicJoint>R_bh_j23_joint</mimicJoint>
      <multiplier>0.344</multiplier>
    </plugin>
  </gazebo>
  <gazebo>
    <plugin filename="libgazebo_mimic_plugin.so" name="mimic_plugin">
      <joint>R_bh_j32_joint</joint>
      <mimicJoint>R_bh_j33_joint</mimicJoint>
      <multiplier>0.344</multiplier>
    </plugin>
  </gazebo>
  <gazebo reference="R_bh_base_link">
    <material>Gazebo/White</material>
    <turnGravityOff>False</turnGravityOff>
  </gazebo>
  <gazebo reference="R_bh_finger_31_link">
    <material>Gazebo/Grey</material>
    <turnGravityOff>False</turnGravityOff>
  </gazebo>
  <gazebo reference="R_bh_finger_32_link">
    <material>Gazebo/Grey</material>
    <turnGravityOff>False</turnGravityOff>
  </gazebo>
  <gazebo reference="R_bh_finger_33_link">
    <material>Gazebo/Grey</material>
    <turnGravityOff>False</turnGravityOff>
  </gazebo>
  <gazebo reference="R_bh_finger_11_link">
    <material>Gazebo/Grey</material>
    <turnGravityOff>False</turnGravityOff>
  </gazebo>
  <gazebo reference="R_bh_finger_12_link">
    <material>Gazebo/Grey</material>
    <turnGravityOff>False</turnGravityOff>
  </gazebo>
  <gazebo reference="R_bh_finger_13_link">
    <material>Gazebo/Grey</material>
    <turnGravityOff>False</turnGravityOff>
  </gazebo>
  <gazebo reference="R_bh_finger_21_link">
    <material>Gazebo/Grey</material>
    <turnGravityOff>False</turnGravityOff>
  </gazebo>
  <gazebo reference="R_bh_finger_22_link">
    <material>Gazebo/Grey</material>
    <turnGravityOff>False</turnGravityOff>
  </gazebo>
  <gazebo reference="R_bh_finger_23_link">
    <material>Gazebo/Grey</material>
    <turnGravityOff>False</turnGravityOff>
  </gazebo>
  <!-- Right Payload -->
  <link name="payloadR">
    <inertial>
      <origin xyz="0.0 0.0 0.0"/>
      <mass value="5"/>
      <inertia ixx="0.00225" ixy="0.0" ixz="0.0" iyy="0.006213" iyz="0.0" izz="0.006213"/>
    </inertial>
    <visual>
      <origin rpy="0 1.57079632679 0" xyz="0.0 0.0 0.0"/>
      <geometry>
        <cylinder length="0.1105" radius="0.06"/>
      </geometry>
      <material name="red"/>
    </visual>
  </link>
  <joint name="bh_to_payloadR" type="fixed">
    <origin rpy="0 0 0" xyz="0 0 0.0855"/>
    <parent link="R_bh_base_link"/>
    <child link="payloadR"/>
  </joint>
  <!-- Left Payload -->
  <link name="payloadL">
    <inertial>
      <origin xyz="0.0 0.0 0.0"/>
      <mass value="0"/>
      <inertia ixx="0.00225" ixy="0.0" ixz="0.0" iyy="0.006213" iyz="0.0" izz="0.006213"/>
    </inertial>
    <visual>
      <origin rpy="0 1.57079632679 0" xyz="0.0 0.0 0.0"/>
      <geometry>
        <cylinder length="0.1105" radius="0.06"/>
      </geometry>
      <material name="red"/>
    </visual>
  </link>
  <joint name="bh_to_payloadL" type="fixed">
    <origin rpy="0 0 0" xyz="0 0 0.0855"/>
    <parent link="L_bh_base_link"/>
    <child link="payloadL"/>
  </joint>
</robot>
